2024-08-07 16:52:10,392  | py-experimenter - INFO     | Found 4 keyfields
2024-08-07 16:52:10,392  | py-experimenter - INFO     | Found 3 resultfields
2024-08-07 16:52:10,392  | py-experimenter - WARNING  | No logtables given
2024-08-07 16:52:10,392  | py-experimenter - WARNING  | No custom section defined in config
2024-08-07 16:52:10,392  | py-experimenter - WARNING  | No codecarbon section defined in config
2024-08-07 16:52:31,876  | py-experimenter - INFO     | Found 4 keyfields
2024-08-07 16:52:31,876  | py-experimenter - INFO     | Found 3 resultfields
2024-08-07 16:52:31,876  | py-experimenter - WARNING  | No logtables given
2024-08-07 16:52:31,876  | py-experimenter - WARNING  | No custom section defined in config
2024-08-07 16:52:31,876  | py-experimenter - WARNING  | No codecarbon section defined in config
2024-08-07 16:53:34,818  | py-experimenter - INFO     | Found 4 keyfields
2024-08-07 16:53:34,818  | py-experimenter - INFO     | Found 3 resultfields
2024-08-07 16:53:34,819  | py-experimenter - WARNING  | No logtables given
2024-08-07 16:53:34,819  | py-experimenter - WARNING  | No custom section defined in config
2024-08-07 16:53:34,819  | py-experimenter - WARNING  | No codecarbon section defined in config
2024-08-07 16:56:05,662  | py-experimenter - INFO     | Found 4 keyfields
2024-08-07 16:56:05,662  | py-experimenter - INFO     | Found 3 resultfields
2024-08-07 16:56:05,662  | py-experimenter - WARNING  | No logtables given
2024-08-07 16:56:05,662  | py-experimenter - WARNING  | No custom section defined in config
2024-08-07 16:56:05,662  | py-experimenter - WARNING  | No codecarbon section defined in config
2024-08-07 16:56:05,685  | py-experimenter - INFO     | Initialized and connected to database
2024-08-07 16:59:54,713  | py-experimenter - INFO     | Found 4 keyfields
2024-08-07 16:59:54,714  | py-experimenter - INFO     | Found 3 resultfields
2024-08-07 16:59:54,714  | py-experimenter - WARNING  | No logtables given
2024-08-07 16:59:54,714  | py-experimenter - WARNING  | No custom section defined in config
2024-08-07 16:59:54,714  | py-experimenter - WARNING  | No codecarbon section defined in config
2024-08-07 16:59:54,732  | py-experimenter - INFO     | Initialized and connected to database
2024-08-07 16:59:54,799  | py-experimenter - INFO     | 12 rows successfully added to database. 0 rows were skipped.
2024-08-07 17:24:19,197  | py-experimenter - INFO     | Found 4 keyfields
2024-08-07 17:24:19,197  | py-experimenter - INFO     | Found 3 resultfields
2024-08-07 17:24:19,198  | py-experimenter - WARNING  | No logtables given
2024-08-07 17:24:19,198  | py-experimenter - WARNING  | No custom section defined in config
2024-08-07 17:24:19,198  | py-experimenter - WARNING  | No codecarbon section defined in config
2024-08-07 17:24:19,208  | py-experimenter - INFO     | Initialized and connected to database
2024-08-07 17:24:19,223  | py-experimenter - INFO     | No rows to add. All the 12 experiments already exist.
2024-08-07 17:27:42,467  | py-experimenter - INFO     | Found 4 keyfields
2024-08-07 17:27:42,468  | py-experimenter - INFO     | Found 3 resultfields
2024-08-07 17:27:42,468  | py-experimenter - WARNING  | No logtables given
2024-08-07 17:27:42,468  | py-experimenter - WARNING  | No custom section defined in config
2024-08-07 17:27:42,469  | py-experimenter - WARNING  | No codecarbon section defined in config
2024-08-07 17:27:42,491  | py-experimenter - INFO     | Initialized and connected to database
2024-08-07 17:27:42,523  | py-experimenter - INFO     | No rows to add. All the 12 experiments already exist.
2024-08-07 17:28:13,216  | py-experimenter - INFO     | Found 4 keyfields
2024-08-07 17:28:13,217  | py-experimenter - INFO     | Found 3 resultfields
2024-08-07 17:28:13,217  | py-experimenter - WARNING  | No logtables given
2024-08-07 17:28:13,217  | py-experimenter - WARNING  | No custom section defined in config
2024-08-07 17:28:13,217  | py-experimenter - WARNING  | No codecarbon section defined in config
2024-08-07 17:28:13,232  | py-experimenter - INFO     | Initialized and connected to database
2024-08-07 17:28:13,257  | py-experimenter - INFO     | No rows to add. All the 12 experiments already exist.
2024-08-07 17:29:46,106  | py-experimenter - INFO     | Found 4 keyfields
2024-08-07 17:29:46,106  | py-experimenter - INFO     | Found 3 resultfields
2024-08-07 17:29:46,106  | py-experimenter - WARNING  | No logtables given
2024-08-07 17:29:46,106  | py-experimenter - WARNING  | No custom section defined in config
2024-08-07 17:29:46,106  | py-experimenter - WARNING  | No codecarbon section defined in config
2024-08-07 17:29:46,120  | py-experimenter - INFO     | Initialized and connected to database
2024-08-07 17:29:46,141  | py-experimenter - INFO     | No rows to add. All the 12 experiments already exist.
2024-08-08 13:26:21,238  | py-experimenter - INFO     | Found 4 keyfields
2024-08-08 13:26:21,239  | py-experimenter - INFO     | Found 3 resultfields
2024-08-08 13:26:21,239  | py-experimenter - WARNING  | No logtables given
2024-08-08 13:26:21,239  | py-experimenter - WARNING  | No custom section defined in config
2024-08-08 13:26:21,239  | py-experimenter - WARNING  | No codecarbon section defined in config
2024-08-09 14:20:00,812  | py-experimenter - INFO     | Found 4 keyfields
2024-08-09 14:20:00,822  | py-experimenter - INFO     | Found 3 resultfields
2024-08-09 14:20:00,822  | py-experimenter - WARNING  | No logtables given
2024-08-09 14:20:00,823  | py-experimenter - WARNING  | No custom section defined in config
2024-08-09 14:20:00,823  | py-experimenter - WARNING  | No codecarbon section defined in config
2024-08-09 14:20:11,054  | py-experimenter - INFO     | Found 4 keyfields
2024-08-09 14:20:11,055  | py-experimenter - INFO     | Found 3 resultfields
2024-08-09 14:20:11,055  | py-experimenter - WARNING  | No logtables given
2024-08-09 14:20:11,055  | py-experimenter - WARNING  | No custom section defined in config
2024-08-09 14:20:11,055  | py-experimenter - WARNING  | No codecarbon section defined in config
2024-08-09 14:24:30,221  | py-experimenter - INFO     | Found 4 keyfields
2024-08-09 14:24:30,221  | py-experimenter - INFO     | Found 3 resultfields
2024-08-09 14:24:30,221  | py-experimenter - WARNING  | No logtables given
2024-08-09 14:24:30,221  | py-experimenter - WARNING  | No custom section defined in config
2024-08-09 14:24:30,222  | py-experimenter - WARNING  | No codecarbon section defined in config
2024-08-09 14:25:20,637  | py-experimenter - INFO     | Found 4 keyfields
2024-08-09 14:25:20,637  | py-experimenter - INFO     | Found 3 resultfields
2024-08-09 14:25:20,637  | py-experimenter - WARNING  | No logtables given
2024-08-09 14:25:20,637  | py-experimenter - WARNING  | No custom section defined in config
2024-08-09 14:25:20,637  | py-experimenter - WARNING  | No codecarbon section defined in config
2024-08-09 14:25:20,647  | py-experimenter - INFO     | Initialized and connected to database
2024-08-09 14:26:04,142  | py-experimenter - INFO     | Found 4 keyfields
2024-08-09 14:26:04,142  | py-experimenter - INFO     | Found 3 resultfields
2024-08-09 14:26:04,142  | py-experimenter - WARNING  | No logtables given
2024-08-09 14:26:04,142  | py-experimenter - WARNING  | No custom section defined in config
2024-08-09 14:26:04,142  | py-experimenter - WARNING  | No codecarbon section defined in config
2024-08-09 14:26:04,143  | py-experimenter - INFO     | Initialized and connected to database
2024-08-09 14:26:04,195  | py-experimenter - INFO     | 12 rows successfully added to database. 0 rows were skipped.
2024-08-09 14:26:13,896  | py-experimenter - INFO     | All configured executions finished.
2024-08-09 14:53:44,320  | py-experimenter - INFO     | Found 4 keyfields
2024-08-09 14:53:44,320  | py-experimenter - INFO     | Found 3 resultfields
2024-08-09 14:53:44,320  | py-experimenter - WARNING  | No logtables given
2024-08-09 14:53:44,320  | py-experimenter - WARNING  | No custom section defined in config
2024-08-09 14:53:44,320  | py-experimenter - WARNING  | No codecarbon section defined in config
2024-08-09 14:53:44,320  | py-experimenter - INFO     | Initialized and connected to database
2024-08-09 14:53:44,321  | py-experimenter - INFO     | No rows to add. All the 12 experiments already exist.
2024-08-09 14:53:58,638  | py-experimenter - INFO     | All configured executions finished.
2024-08-09 15:19:10,535  | py-experimenter - INFO     | Found 5 keyfields
2024-08-09 15:19:10,536  | py-experimenter - INFO     | Found 3 resultfields
2024-08-09 15:19:10,537  | py-experimenter - WARNING  | No logtables given
2024-08-09 15:19:10,538  | py-experimenter - WARNING  | No custom section defined in config
2024-08-09 15:19:10,538  | py-experimenter - WARNING  | No codecarbon section defined in config
2024-08-09 15:19:10,540  | py-experimenter - INFO     | Initialized and connected to database
2024-08-09 15:19:10,587  | py-experimenter - INFO     | 12 rows successfully added to database. 0 rows were skipped.
2024-08-09 15:19:35,223  | py-experimenter - INFO     | All configured executions finished.
2024-08-09 15:20:04,260  | py-experimenter - INFO     | Found 5 keyfields
2024-08-09 15:20:04,260  | py-experimenter - INFO     | Found 3 resultfields
2024-08-09 15:20:04,260  | py-experimenter - WARNING  | No logtables given
2024-08-09 15:20:04,260  | py-experimenter - WARNING  | No custom section defined in config
2024-08-09 15:20:04,260  | py-experimenter - WARNING  | No codecarbon section defined in config
2024-08-09 15:20:04,261  | py-experimenter - INFO     | Initialized and connected to database
2024-08-09 15:20:04,262  | py-experimenter - INFO     | No rows to add. All the 12 experiments already exist.
2024-08-09 15:31:13,878  | py-experimenter - INFO     | Found 5 keyfields
2024-08-09 15:31:13,878  | py-experimenter - INFO     | Found 3 resultfields
2024-08-09 15:31:13,878  | py-experimenter - WARNING  | No logtables given
2024-08-09 15:31:13,878  | py-experimenter - WARNING  | No custom section defined in config
2024-08-09 15:31:13,878  | py-experimenter - WARNING  | No codecarbon section defined in config
2024-08-09 15:31:13,878  | py-experimenter - INFO     | Initialized and connected to database
2024-08-09 15:31:13,879  | py-experimenter - INFO     | No rows to add. All the 12 experiments already exist.
2024-08-09 15:31:49,806  | py-experimenter - INFO     | Found 5 keyfields
2024-08-09 15:31:49,806  | py-experimenter - INFO     | Found 3 resultfields
2024-08-09 15:31:49,806  | py-experimenter - WARNING  | No logtables given
2024-08-09 15:31:49,806  | py-experimenter - WARNING  | No custom section defined in config
2024-08-09 15:31:49,806  | py-experimenter - WARNING  | No codecarbon section defined in config
2024-08-09 15:31:49,806  | py-experimenter - INFO     | Initialized and connected to database
2024-08-09 15:31:49,858  | py-experimenter - INFO     | 12 rows successfully added to database. 0 rows were skipped.
2024-08-09 15:31:55,872  | py-experimenter - INFO     | All configured executions finished.
2024-08-09 15:34:35,142  | py-experimenter - INFO     | Found 5 keyfields
2024-08-09 15:34:35,142  | py-experimenter - INFO     | Found 3 resultfields
2024-08-09 15:34:35,142  | py-experimenter - WARNING  | No logtables given
2024-08-09 15:34:35,142  | py-experimenter - WARNING  | No custom section defined in config
2024-08-09 15:34:35,142  | py-experimenter - WARNING  | No codecarbon section defined in config
2024-08-09 15:34:35,142  | py-experimenter - INFO     | Initialized and connected to database
2024-08-09 15:34:35,143  | py-experimenter - INFO     | No rows to add. All the 12 experiments already exist.
2024-08-09 15:34:41,138  | py-experimenter - INFO     | All configured executions finished.
2024-08-09 15:35:31,729  | py-experimenter - INFO     | Found 5 keyfields
2024-08-09 15:35:31,730  | py-experimenter - INFO     | Found 3 resultfields
2024-08-09 15:35:31,730  | py-experimenter - WARNING  | No logtables given
2024-08-09 15:35:31,730  | py-experimenter - WARNING  | No custom section defined in config
2024-08-09 15:35:31,730  | py-experimenter - WARNING  | No codecarbon section defined in config
2024-08-09 15:35:31,730  | py-experimenter - INFO     | Initialized and connected to database
2024-08-09 15:35:31,731  | py-experimenter - INFO     | No rows to add. All the 12 experiments already exist.
2024-08-09 15:35:38,551  | py-experimenter - INFO     | All configured executions finished.
2024-08-12 09:30:12,137  | py-experimenter - INFO     | Found 5 keyfields
2024-08-12 09:30:12,137  | py-experimenter - INFO     | Found 3 resultfields
2024-08-12 09:30:12,137  | py-experimenter - WARNING  | No logtables given
2024-08-12 09:30:12,137  | py-experimenter - WARNING  | No custom section defined in config
2024-08-12 09:30:12,137  | py-experimenter - WARNING  | No codecarbon section defined in config
2024-08-12 09:30:12,137  | py-experimenter - INFO     | Initialized and connected to database
2024-08-12 09:30:12,138  | py-experimenter - INFO     | No rows to add. All the 12 experiments already exist.
2024-08-12 09:30:18,730  | py-experimenter - INFO     | All configured executions finished.
2024-08-12 09:36:38,300  | py-experimenter - INFO     | Found 5 keyfields
2024-08-12 09:36:38,300  | py-experimenter - INFO     | Found 3 resultfields
2024-08-12 09:36:38,300  | py-experimenter - WARNING  | No logtables given
2024-08-12 09:36:38,301  | py-experimenter - WARNING  | No custom section defined in config
2024-08-12 09:36:38,301  | py-experimenter - WARNING  | No codecarbon section defined in config
2024-08-12 09:36:38,301  | py-experimenter - INFO     | Initialized and connected to database
2024-08-12 09:36:38,301  | py-experimenter - INFO     | No rows to add. All the 12 experiments already exist.
2024-08-12 09:36:44,382  | py-experimenter - INFO     | All configured executions finished.
2024-08-12 09:47:51,343  | py-experimenter - INFO     | Found 5 keyfields
2024-08-12 09:47:51,344  | py-experimenter - INFO     | Found 3 resultfields
2024-08-12 09:47:51,344  | py-experimenter - WARNING  | No logtables given
2024-08-12 09:47:51,344  | py-experimenter - WARNING  | No custom section defined in config
2024-08-12 09:47:51,344  | py-experimenter - WARNING  | No codecarbon section defined in config
2024-08-12 09:47:51,344  | py-experimenter - INFO     | Initialized and connected to database
2024-08-12 09:47:51,344  | py-experimenter - INFO     | No rows to add. All the 12 experiments already exist.
2024-08-12 09:47:57,372  | py-experimenter - INFO     | All configured executions finished.
2024-08-12 09:48:51,065  | py-experimenter - INFO     | Found 5 keyfields
2024-08-12 09:48:51,065  | py-experimenter - INFO     | Found 3 resultfields
2024-08-12 09:48:51,065  | py-experimenter - WARNING  | No logtables given
2024-08-12 09:48:51,065  | py-experimenter - WARNING  | No custom section defined in config
2024-08-12 09:48:51,065  | py-experimenter - WARNING  | No codecarbon section defined in config
2024-08-12 09:48:51,066  | py-experimenter - INFO     | Initialized and connected to database
2024-08-12 09:48:51,067  | py-experimenter - INFO     | No rows to add. All the 12 experiments already exist.
2024-08-12 09:48:58,728  | py-experimenter - INFO     | All configured executions finished.
2024-08-12 09:49:13,764  | py-experimenter - INFO     | Found 5 keyfields
2024-08-12 09:49:13,764  | py-experimenter - INFO     | Found 3 resultfields
2024-08-12 09:49:13,764  | py-experimenter - WARNING  | No logtables given
2024-08-12 09:49:13,764  | py-experimenter - WARNING  | No custom section defined in config
2024-08-12 09:49:13,764  | py-experimenter - WARNING  | No codecarbon section defined in config
2024-08-12 09:49:13,764  | py-experimenter - INFO     | Initialized and connected to database
2024-08-12 09:49:13,765  | py-experimenter - INFO     | No rows to add. All the 12 experiments already exist.
2024-08-12 09:49:21,659  | py-experimenter - INFO     | All configured executions finished.
2024-08-12 15:38:15,686  | py-experimenter - INFO     | Found 6 keyfields
2024-08-12 15:38:15,686  | py-experimenter - INFO     | Found 8 resultfields
2024-08-12 15:38:15,686  | py-experimenter - WARNING  | No logtables given
2024-08-12 15:38:15,686  | py-experimenter - WARNING  | No custom section defined in config
2024-08-12 15:38:15,687  | py-experimenter - WARNING  | No codecarbon section defined in config
2024-08-12 15:38:15,687  | py-experimenter - INFO     | Initialized and connected to database
2024-08-12 15:38:15,738  | py-experimenter - INFO     | 1 rows successfully added to database. 0 rows were skipped.
2024-08-12 15:38:21,981  | py-experimenter - INFO     | All configured executions finished.
2024-08-12 16:42:28,199  | py-experimenter - INFO     | Found 6 keyfields
2024-08-12 16:42:28,200  | py-experimenter - INFO     | Found 8 resultfields
2024-08-12 16:42:28,200  | py-experimenter - WARNING  | No logtables given
2024-08-12 16:42:28,200  | py-experimenter - WARNING  | No custom section defined in config
2024-08-12 16:42:28,200  | py-experimenter - WARNING  | No codecarbon section defined in config
2024-08-12 16:42:28,200  | py-experimenter - INFO     | Initialized and connected to database
2024-08-12 16:42:28,201  | py-experimenter - INFO     | No rows to add. All the 1 experiments already exist.
2024-08-12 16:42:54,535  | py-experimenter - INFO     | Found 6 keyfields
2024-08-12 16:42:54,535  | py-experimenter - INFO     | Found 8 resultfields
2024-08-12 16:42:54,535  | py-experimenter - WARNING  | No logtables given
2024-08-12 16:42:54,535  | py-experimenter - WARNING  | No custom section defined in config
2024-08-12 16:42:54,535  | py-experimenter - WARNING  | No codecarbon section defined in config
2024-08-12 16:42:54,536  | py-experimenter - INFO     | Initialized and connected to database
2024-08-12 16:42:54,588  | py-experimenter - INFO     | 1 rows successfully added to database. 0 rows were skipped.
2024-08-12 16:43:00,841  | py-experimenter - INFO     | All configured executions finished.
2024-08-12 16:43:25,132  | py-experimenter - INFO     | Found 6 keyfields
2024-08-12 16:43:25,133  | py-experimenter - INFO     | Found 8 resultfields
2024-08-12 16:43:25,133  | py-experimenter - WARNING  | No logtables given
2024-08-12 16:43:25,133  | py-experimenter - WARNING  | No custom section defined in config
2024-08-12 16:43:25,133  | py-experimenter - WARNING  | No codecarbon section defined in config
2024-08-12 16:43:25,133  | py-experimenter - INFO     | Initialized and connected to database
2024-08-12 16:43:25,133  | py-experimenter - INFO     | No rows to add. All the 1 experiments already exist.
2024-08-12 16:43:34,705  | py-experimenter - INFO     | Found 6 keyfields
2024-08-12 16:43:34,705  | py-experimenter - INFO     | Found 8 resultfields
2024-08-12 16:43:34,705  | py-experimenter - WARNING  | No logtables given
2024-08-12 16:43:34,706  | py-experimenter - WARNING  | No custom section defined in config
2024-08-12 16:43:34,706  | py-experimenter - WARNING  | No codecarbon section defined in config
2024-08-12 16:43:34,706  | py-experimenter - INFO     | Initialized and connected to database
2024-08-12 16:43:34,756  | py-experimenter - INFO     | 1 rows successfully added to database. 0 rows were skipped.
2024-08-12 16:43:40,990  | py-experimenter - INFO     | All configured executions finished.
2024-08-14 09:34:46,333  | py-experimenter - INFO     | Found 6 keyfields
2024-08-14 09:34:46,333  | py-experimenter - INFO     | Found 7 resultfields
2024-08-14 09:34:46,333  | py-experimenter - WARNING  | No logtables given
2024-08-14 09:34:46,333  | py-experimenter - WARNING  | No custom section defined in config
2024-08-14 09:34:46,333  | py-experimenter - WARNING  | No codecarbon section defined in config
2024-08-14 09:34:46,333  | py-experimenter - INFO     | Initialized and connected to database
2024-08-14 09:34:46,386  | py-experimenter - INFO     | 6 rows successfully added to database. 0 rows were skipped.
2024-08-14 09:35:22,606  | py-experimenter - INFO     | All configured executions finished.
2024-08-14 12:04:25,657  | py-experimenter - INFO     | Found 5 keyfields
2024-08-14 12:04:25,667  | py-experimenter - INFO     | Found 9 resultfields
2024-08-14 12:04:25,667  | py-experimenter - WARNING  | No logtables given
2024-08-14 12:04:25,667  | py-experimenter - WARNING  | No custom section defined in config
2024-08-14 12:04:25,667  | py-experimenter - WARNING  | No codecarbon section defined in config
2024-08-14 12:04:25,682  | py-experimenter - INFO     | Initialized and connected to database
2024-08-14 12:04:25,726  | py-experimenter - INFO     | 3 rows successfully added to database. 0 rows were skipped.
2024-08-14 12:05:54,622  | py-experimenter - INFO     | Found 5 keyfields
2024-08-14 12:05:54,623  | py-experimenter - INFO     | Found 9 resultfields
2024-08-14 12:05:54,623  | py-experimenter - WARNING  | No logtables given
2024-08-14 12:05:54,623  | py-experimenter - WARNING  | No custom section defined in config
2024-08-14 12:05:54,623  | py-experimenter - WARNING  | No codecarbon section defined in config
2024-08-14 12:05:54,636  | py-experimenter - INFO     | Initialized and connected to database
2024-08-14 12:05:54,659  | py-experimenter - INFO     | No rows to add. All the 3 experiments already exist.
2024-08-14 12:05:59,427  | py-experimenter - ERROR    | Traceback (most recent call last):
  File "/home/jonas/Documents/Research/dyad_ranking/torch_plnet/.venv/lib/python3.11/site-packages/mysql/connector/connection_cext.py", line 705, in cmd_query
    self._cmysql.query(
_mysql_connector.MySQLInterfaceError: Out of range value for column 'mccv_seed' at row 1

The above exception was the direct cause of the following exception:

Traceback (most recent call last):
  File "/home/jonas/Documents/Research/dyad_ranking/torch_plnet/.venv/lib/python3.11/site-packages/py_experimenter/database_connector.py", line 57, in execute
    cursor.execute(sql_statement, values)
  File "/home/jonas/Documents/Research/dyad_ranking/torch_plnet/.venv/lib/python3.11/site-packages/mysql/connector/cursor_cext.py", line 357, in execute
    result = self._connection.cmd_query(
             ^^^^^^^^^^^^^^^^^^^^^^^^^^^
  File "/home/jonas/Documents/Research/dyad_ranking/torch_plnet/.venv/lib/python3.11/site-packages/mysql/connector/opentelemetry/context_propagation.py", line 97, in wrapper
    return method(cnx, *args, **kwargs)
           ^^^^^^^^^^^^^^^^^^^^^^^^^^^^
  File "/home/jonas/Documents/Research/dyad_ranking/torch_plnet/.venv/lib/python3.11/site-packages/mysql/connector/connection_cext.py", line 713, in cmd_query
    raise get_mysql_exception(
mysql.connector.errors.DataError: 1264 (22003): Out of range value for column 'mccv_seed' at row 1

During handling of the above exception, another exception occurred:

Traceback (most recent call last):
  File "/home/jonas/Documents/Research/dyad_ranking/torch_plnet/.venv/lib/python3.11/site-packages/py_experimenter/experimenter.py", line 433, in _execute_experiment
    final_status = experiment_function(keyfield_values, result_processor, self.config.custom_configuration.custom_values)
                   ^^^^^^^^^^^^^^^^^^^^^^^^^^^^^^^^^^^^^^^^^^^^^^^^^^^^^^^^^^^^^^^^^^^^^^^^^^^^^^^^^^^^^^^^^^^^^^^^^^^^^^
  File "/home/jonas/Documents/Research/dyad_ranking/torch_plnet/experiments/cp_rank_experimenter.py", line 174, in worker
    result_processor.process_results(
  File "/home/jonas/Documents/Research/dyad_ranking/torch_plnet/.venv/lib/python3.11/site-packages/py_experimenter/result_processor.py", line 45, in process_results
    self.db_connector.update_database(self.database_config.table_name, values=results, condition=self.experiment_id_condition)
  File "/home/jonas/Documents/Research/dyad_ranking/torch_plnet/.venv/lib/python3.11/site-packages/py_experimenter/database_connector.py", line 314, in update_database
    self.execute(cursor, self._prepare_update_query(table_name, values.keys(), condition), list(values.values()))
  File "/home/jonas/Documents/Research/dyad_ranking/torch_plnet/.venv/lib/python3.11/site-packages/py_experimenter/database_connector.py", line 59, in execute
    raise DatabaseConnectionError(f"error \n{e}\n raised when executing sql statement.")
py_experimenter.exceptions.DatabaseConnectionError: error 
1264 (22003): Out of range value for column 'mccv_seed' at row 1
 raised when executing sql statement.

2024-08-14 12:06:01,064  | py-experimenter - ERROR    | Traceback (most recent call last):
  File "/home/jonas/Documents/Research/dyad_ranking/torch_plnet/.venv/lib/python3.11/site-packages/mysql/connector/connection_cext.py", line 705, in cmd_query
    self._cmysql.query(
_mysql_connector.MySQLInterfaceError: Out of range value for column 'mccv_seed' at row 1

The above exception was the direct cause of the following exception:

Traceback (most recent call last):
  File "/home/jonas/Documents/Research/dyad_ranking/torch_plnet/.venv/lib/python3.11/site-packages/py_experimenter/database_connector.py", line 57, in execute
    cursor.execute(sql_statement, values)
  File "/home/jonas/Documents/Research/dyad_ranking/torch_plnet/.venv/lib/python3.11/site-packages/mysql/connector/cursor_cext.py", line 357, in execute
    result = self._connection.cmd_query(
             ^^^^^^^^^^^^^^^^^^^^^^^^^^^
  File "/home/jonas/Documents/Research/dyad_ranking/torch_plnet/.venv/lib/python3.11/site-packages/mysql/connector/opentelemetry/context_propagation.py", line 97, in wrapper
    return method(cnx, *args, **kwargs)
           ^^^^^^^^^^^^^^^^^^^^^^^^^^^^
  File "/home/jonas/Documents/Research/dyad_ranking/torch_plnet/.venv/lib/python3.11/site-packages/mysql/connector/connection_cext.py", line 713, in cmd_query
    raise get_mysql_exception(
mysql.connector.errors.DataError: 1264 (22003): Out of range value for column 'mccv_seed' at row 1

During handling of the above exception, another exception occurred:

Traceback (most recent call last):
  File "/home/jonas/Documents/Research/dyad_ranking/torch_plnet/.venv/lib/python3.11/site-packages/py_experimenter/experimenter.py", line 433, in _execute_experiment
    final_status = experiment_function(keyfield_values, result_processor, self.config.custom_configuration.custom_values)
                   ^^^^^^^^^^^^^^^^^^^^^^^^^^^^^^^^^^^^^^^^^^^^^^^^^^^^^^^^^^^^^^^^^^^^^^^^^^^^^^^^^^^^^^^^^^^^^^^^^^^^^^
  File "/home/jonas/Documents/Research/dyad_ranking/torch_plnet/experiments/cp_rank_experimenter.py", line 174, in worker
    result_processor.process_results(
  File "/home/jonas/Documents/Research/dyad_ranking/torch_plnet/.venv/lib/python3.11/site-packages/py_experimenter/result_processor.py", line 45, in process_results
    self.db_connector.update_database(self.database_config.table_name, values=results, condition=self.experiment_id_condition)
  File "/home/jonas/Documents/Research/dyad_ranking/torch_plnet/.venv/lib/python3.11/site-packages/py_experimenter/database_connector.py", line 314, in update_database
    self.execute(cursor, self._prepare_update_query(table_name, values.keys(), condition), list(values.values()))
  File "/home/jonas/Documents/Research/dyad_ranking/torch_plnet/.venv/lib/python3.11/site-packages/py_experimenter/database_connector.py", line 59, in execute
    raise DatabaseConnectionError(f"error \n{e}\n raised when executing sql statement.")
py_experimenter.exceptions.DatabaseConnectionError: error 
1264 (22003): Out of range value for column 'mccv_seed' at row 1
 raised when executing sql statement.

2024-08-14 12:06:01,695  | py-experimenter - ERROR    | Traceback (most recent call last):
  File "/home/jonas/Documents/Research/dyad_ranking/torch_plnet/.venv/lib/python3.11/site-packages/mysql/connector/connection_cext.py", line 705, in cmd_query
    self._cmysql.query(
_mysql_connector.MySQLInterfaceError: Out of range value for column 'mccv_seed' at row 1

The above exception was the direct cause of the following exception:

Traceback (most recent call last):
  File "/home/jonas/Documents/Research/dyad_ranking/torch_plnet/.venv/lib/python3.11/site-packages/py_experimenter/database_connector.py", line 57, in execute
    cursor.execute(sql_statement, values)
  File "/home/jonas/Documents/Research/dyad_ranking/torch_plnet/.venv/lib/python3.11/site-packages/mysql/connector/cursor_cext.py", line 357, in execute
    result = self._connection.cmd_query(
             ^^^^^^^^^^^^^^^^^^^^^^^^^^^
  File "/home/jonas/Documents/Research/dyad_ranking/torch_plnet/.venv/lib/python3.11/site-packages/mysql/connector/opentelemetry/context_propagation.py", line 97, in wrapper
    return method(cnx, *args, **kwargs)
           ^^^^^^^^^^^^^^^^^^^^^^^^^^^^
  File "/home/jonas/Documents/Research/dyad_ranking/torch_plnet/.venv/lib/python3.11/site-packages/mysql/connector/connection_cext.py", line 713, in cmd_query
    raise get_mysql_exception(
mysql.connector.errors.DataError: 1264 (22003): Out of range value for column 'mccv_seed' at row 1

During handling of the above exception, another exception occurred:

Traceback (most recent call last):
  File "/home/jonas/Documents/Research/dyad_ranking/torch_plnet/.venv/lib/python3.11/site-packages/py_experimenter/experimenter.py", line 433, in _execute_experiment
    final_status = experiment_function(keyfield_values, result_processor, self.config.custom_configuration.custom_values)
                   ^^^^^^^^^^^^^^^^^^^^^^^^^^^^^^^^^^^^^^^^^^^^^^^^^^^^^^^^^^^^^^^^^^^^^^^^^^^^^^^^^^^^^^^^^^^^^^^^^^^^^^
  File "/home/jonas/Documents/Research/dyad_ranking/torch_plnet/experiments/cp_rank_experimenter.py", line 174, in worker
    result_processor.process_results(
  File "/home/jonas/Documents/Research/dyad_ranking/torch_plnet/.venv/lib/python3.11/site-packages/py_experimenter/result_processor.py", line 45, in process_results
    self.db_connector.update_database(self.database_config.table_name, values=results, condition=self.experiment_id_condition)
  File "/home/jonas/Documents/Research/dyad_ranking/torch_plnet/.venv/lib/python3.11/site-packages/py_experimenter/database_connector.py", line 314, in update_database
    self.execute(cursor, self._prepare_update_query(table_name, values.keys(), condition), list(values.values()))
  File "/home/jonas/Documents/Research/dyad_ranking/torch_plnet/.venv/lib/python3.11/site-packages/py_experimenter/database_connector.py", line 59, in execute
    raise DatabaseConnectionError(f"error \n{e}\n raised when executing sql statement.")
py_experimenter.exceptions.DatabaseConnectionError: error 
1264 (22003): Out of range value for column 'mccv_seed' at row 1
 raised when executing sql statement.

2024-08-14 12:12:03,116  | py-experimenter - INFO     | Found 5 keyfields
2024-08-14 12:12:03,116  | py-experimenter - INFO     | Found 9 resultfields
2024-08-14 12:12:03,116  | py-experimenter - WARNING  | No logtables given
2024-08-14 12:12:03,116  | py-experimenter - WARNING  | No custom section defined in config
2024-08-14 12:12:03,116  | py-experimenter - WARNING  | No codecarbon section defined in config
2024-08-14 12:12:03,129  | py-experimenter - INFO     | Initialized and connected to database
2024-08-14 12:12:03,182  | py-experimenter - INFO     | 3 rows successfully added to database. 0 rows were skipped.
2024-08-14 12:12:08,913  | py-experimenter - INFO     | All configured executions finished.
2024-08-14 12:13:15,156  | py-experimenter - INFO     | Found 5 keyfields
2024-08-14 12:13:15,156  | py-experimenter - INFO     | Found 9 resultfields
2024-08-14 12:13:15,156  | py-experimenter - WARNING  | No logtables given
2024-08-14 12:13:15,157  | py-experimenter - WARNING  | No custom section defined in config
2024-08-14 12:13:15,157  | py-experimenter - WARNING  | No codecarbon section defined in config
2024-08-14 12:13:15,169  | py-experimenter - INFO     | Initialized and connected to database
2024-08-14 12:13:15,205  | py-experimenter - INFO     | 12 rows successfully added to database. 3 rows were skipped.
2024-08-14 12:15:42,891  | py-experimenter - INFO     | All configured executions finished.
2024-08-21 11:10:05,578  | py-experimenter - INFO     | Found 5 keyfields
2024-08-21 11:10:05,579  | py-experimenter - INFO     | Found 9 resultfields
2024-08-21 11:10:05,579  | py-experimenter - WARNING  | No logtables given
2024-08-21 11:10:05,579  | py-experimenter - WARNING  | No custom section defined in config
2024-08-21 11:10:05,579  | py-experimenter - WARNING  | No codecarbon section defined in config
2024-08-21 11:10:05,579  | py-experimenter - INFO     | Initialized and connected to database
2024-08-21 11:10:05,626  | py-experimenter - INFO     | 120 rows successfully added to database. 0 rows were skipped.
2024-08-21 11:10:11,862  | py-experimenter - ERROR    | Traceback (most recent call last):
  File "/home/jonas/Documents/Research/dyad_ranking/torch_plnet/.venv/lib/python3.11/site-packages/py_experimenter/experimenter.py", line 433, in _execute_experiment
    final_status = experiment_function(keyfield_values, result_processor, self.config.custom_configuration.custom_values)
                   ^^^^^^^^^^^^^^^^^^^^^^^^^^^^^^^^^^^^^^^^^^^^^^^^^^^^^^^^^^^^^^^^^^^^^^^^^^^^^^^^^^^^^^^^^^^^^^^^^^^^^^
  File "/home/jonas/Documents/Research/dyad_ranking/torch_plnet/experiments/cp_rank_experimenter.py", line 152, in worker
    predictor.fit(
  File "/home/jonas/Documents/Research/dyad_ranking/torch_plnet/simple_model.py", line 387, in fit
    self.threshold = np.quantile(
                     ^^^^^^^^^^^^
  File "/home/jonas/Documents/Research/dyad_ranking/torch_plnet/.venv/lib/python3.11/site-packages/numpy/lib/function_base.py", line 4542, in quantile
    raise ValueError("Quantiles must be in the range [0, 1]")
ValueError: Quantiles must be in the range [0, 1]

2024-08-21 11:10:11,935  | py-experimenter - ERROR    | Traceback (most recent call last):
  File "/home/jonas/Documents/Research/dyad_ranking/torch_plnet/.venv/lib/python3.11/site-packages/py_experimenter/experimenter.py", line 433, in _execute_experiment
    final_status = experiment_function(keyfield_values, result_processor, self.config.custom_configuration.custom_values)
                   ^^^^^^^^^^^^^^^^^^^^^^^^^^^^^^^^^^^^^^^^^^^^^^^^^^^^^^^^^^^^^^^^^^^^^^^^^^^^^^^^^^^^^^^^^^^^^^^^^^^^^^
  File "/home/jonas/Documents/Research/dyad_ranking/torch_plnet/experiments/cp_rank_experimenter.py", line 152, in worker
    predictor.fit(
  File "/home/jonas/Documents/Research/dyad_ranking/torch_plnet/simple_model.py", line 387, in fit
    self.threshold = np.quantile(
                     ^^^^^^^^^^^^
  File "/home/jonas/Documents/Research/dyad_ranking/torch_plnet/.venv/lib/python3.11/site-packages/numpy/lib/function_base.py", line 4542, in quantile
    raise ValueError("Quantiles must be in the range [0, 1]")
ValueError: Quantiles must be in the range [0, 1]

2024-08-21 11:10:12,137  | py-experimenter - ERROR    | Traceback (most recent call last):
  File "/home/jonas/Documents/Research/dyad_ranking/torch_plnet/.venv/lib/python3.11/site-packages/py_experimenter/experimenter.py", line 433, in _execute_experiment
    final_status = experiment_function(keyfield_values, result_processor, self.config.custom_configuration.custom_values)
                   ^^^^^^^^^^^^^^^^^^^^^^^^^^^^^^^^^^^^^^^^^^^^^^^^^^^^^^^^^^^^^^^^^^^^^^^^^^^^^^^^^^^^^^^^^^^^^^^^^^^^^^
  File "/home/jonas/Documents/Research/dyad_ranking/torch_plnet/experiments/cp_rank_experimenter.py", line 152, in worker
    predictor.fit(
  File "/home/jonas/Documents/Research/dyad_ranking/torch_plnet/simple_model.py", line 387, in fit
    self.threshold = np.quantile(
                     ^^^^^^^^^^^^
  File "/home/jonas/Documents/Research/dyad_ranking/torch_plnet/.venv/lib/python3.11/site-packages/numpy/lib/function_base.py", line 4542, in quantile
    raise ValueError("Quantiles must be in the range [0, 1]")
ValueError: Quantiles must be in the range [0, 1]

2024-08-21 11:10:12,290  | py-experimenter - ERROR    | Traceback (most recent call last):
  File "/home/jonas/Documents/Research/dyad_ranking/torch_plnet/.venv/lib/python3.11/site-packages/py_experimenter/experimenter.py", line 433, in _execute_experiment
    final_status = experiment_function(keyfield_values, result_processor, self.config.custom_configuration.custom_values)
                   ^^^^^^^^^^^^^^^^^^^^^^^^^^^^^^^^^^^^^^^^^^^^^^^^^^^^^^^^^^^^^^^^^^^^^^^^^^^^^^^^^^^^^^^^^^^^^^^^^^^^^^
  File "/home/jonas/Documents/Research/dyad_ranking/torch_plnet/experiments/cp_rank_experimenter.py", line 152, in worker
    predictor.fit(
  File "/home/jonas/Documents/Research/dyad_ranking/torch_plnet/simple_model.py", line 387, in fit
    self.threshold = np.quantile(
                     ^^^^^^^^^^^^
  File "/home/jonas/Documents/Research/dyad_ranking/torch_plnet/.venv/lib/python3.11/site-packages/numpy/lib/function_base.py", line 4542, in quantile
    raise ValueError("Quantiles must be in the range [0, 1]")
ValueError: Quantiles must be in the range [0, 1]

2024-08-21 11:10:12,323  | py-experimenter - ERROR    | Traceback (most recent call last):
  File "/home/jonas/Documents/Research/dyad_ranking/torch_plnet/.venv/lib/python3.11/site-packages/py_experimenter/experimenter.py", line 433, in _execute_experiment
    final_status = experiment_function(keyfield_values, result_processor, self.config.custom_configuration.custom_values)
                   ^^^^^^^^^^^^^^^^^^^^^^^^^^^^^^^^^^^^^^^^^^^^^^^^^^^^^^^^^^^^^^^^^^^^^^^^^^^^^^^^^^^^^^^^^^^^^^^^^^^^^^
  File "/home/jonas/Documents/Research/dyad_ranking/torch_plnet/experiments/cp_rank_experimenter.py", line 152, in worker
    predictor.fit(
  File "/home/jonas/Documents/Research/dyad_ranking/torch_plnet/simple_model.py", line 387, in fit
    self.threshold = np.quantile(
                     ^^^^^^^^^^^^
  File "/home/jonas/Documents/Research/dyad_ranking/torch_plnet/.venv/lib/python3.11/site-packages/numpy/lib/function_base.py", line 4542, in quantile
    raise ValueError("Quantiles must be in the range [0, 1]")
ValueError: Quantiles must be in the range [0, 1]

2024-08-21 11:10:12,388  | py-experimenter - ERROR    | Traceback (most recent call last):
  File "/home/jonas/Documents/Research/dyad_ranking/torch_plnet/.venv/lib/python3.11/site-packages/py_experimenter/experimenter.py", line 433, in _execute_experiment
    final_status = experiment_function(keyfield_values, result_processor, self.config.custom_configuration.custom_values)
                   ^^^^^^^^^^^^^^^^^^^^^^^^^^^^^^^^^^^^^^^^^^^^^^^^^^^^^^^^^^^^^^^^^^^^^^^^^^^^^^^^^^^^^^^^^^^^^^^^^^^^^^
  File "/home/jonas/Documents/Research/dyad_ranking/torch_plnet/experiments/cp_rank_experimenter.py", line 152, in worker
    predictor.fit(
  File "/home/jonas/Documents/Research/dyad_ranking/torch_plnet/simple_model.py", line 387, in fit
    self.threshold = np.quantile(
                     ^^^^^^^^^^^^
  File "/home/jonas/Documents/Research/dyad_ranking/torch_plnet/.venv/lib/python3.11/site-packages/numpy/lib/function_base.py", line 4542, in quantile
    raise ValueError("Quantiles must be in the range [0, 1]")
ValueError: Quantiles must be in the range [0, 1]

2024-08-21 11:10:12,390  | py-experimenter - ERROR    | Traceback (most recent call last):
  File "/home/jonas/Documents/Research/dyad_ranking/torch_plnet/.venv/lib/python3.11/site-packages/py_experimenter/experimenter.py", line 433, in _execute_experiment
    final_status = experiment_function(keyfield_values, result_processor, self.config.custom_configuration.custom_values)
                   ^^^^^^^^^^^^^^^^^^^^^^^^^^^^^^^^^^^^^^^^^^^^^^^^^^^^^^^^^^^^^^^^^^^^^^^^^^^^^^^^^^^^^^^^^^^^^^^^^^^^^^
  File "/home/jonas/Documents/Research/dyad_ranking/torch_plnet/experiments/cp_rank_experimenter.py", line 152, in worker
    predictor.fit(
  File "/home/jonas/Documents/Research/dyad_ranking/torch_plnet/simple_model.py", line 387, in fit
    self.threshold = np.quantile(
                     ^^^^^^^^^^^^
  File "/home/jonas/Documents/Research/dyad_ranking/torch_plnet/.venv/lib/python3.11/site-packages/numpy/lib/function_base.py", line 4542, in quantile
    raise ValueError("Quantiles must be in the range [0, 1]")
ValueError: Quantiles must be in the range [0, 1]

2024-08-21 11:10:12,496  | py-experimenter - ERROR    | Traceback (most recent call last):
  File "/home/jonas/Documents/Research/dyad_ranking/torch_plnet/.venv/lib/python3.11/site-packages/py_experimenter/experimenter.py", line 433, in _execute_experiment
    final_status = experiment_function(keyfield_values, result_processor, self.config.custom_configuration.custom_values)
                   ^^^^^^^^^^^^^^^^^^^^^^^^^^^^^^^^^^^^^^^^^^^^^^^^^^^^^^^^^^^^^^^^^^^^^^^^^^^^^^^^^^^^^^^^^^^^^^^^^^^^^^
  File "/home/jonas/Documents/Research/dyad_ranking/torch_plnet/experiments/cp_rank_experimenter.py", line 152, in worker
    predictor.fit(
  File "/home/jonas/Documents/Research/dyad_ranking/torch_plnet/simple_model.py", line 387, in fit
    self.threshold = np.quantile(
                     ^^^^^^^^^^^^
  File "/home/jonas/Documents/Research/dyad_ranking/torch_plnet/.venv/lib/python3.11/site-packages/numpy/lib/function_base.py", line 4542, in quantile
    raise ValueError("Quantiles must be in the range [0, 1]")
ValueError: Quantiles must be in the range [0, 1]

2024-08-21 11:10:12,505  | py-experimenter - ERROR    | Traceback (most recent call last):
  File "/home/jonas/Documents/Research/dyad_ranking/torch_plnet/.venv/lib/python3.11/site-packages/py_experimenter/experimenter.py", line 433, in _execute_experiment
    final_status = experiment_function(keyfield_values, result_processor, self.config.custom_configuration.custom_values)
                   ^^^^^^^^^^^^^^^^^^^^^^^^^^^^^^^^^^^^^^^^^^^^^^^^^^^^^^^^^^^^^^^^^^^^^^^^^^^^^^^^^^^^^^^^^^^^^^^^^^^^^^
  File "/home/jonas/Documents/Research/dyad_ranking/torch_plnet/experiments/cp_rank_experimenter.py", line 152, in worker
    predictor.fit(
  File "/home/jonas/Documents/Research/dyad_ranking/torch_plnet/simple_model.py", line 387, in fit
    self.threshold = np.quantile(
                     ^^^^^^^^^^^^
  File "/home/jonas/Documents/Research/dyad_ranking/torch_plnet/.venv/lib/python3.11/site-packages/numpy/lib/function_base.py", line 4542, in quantile
    raise ValueError("Quantiles must be in the range [0, 1]")
ValueError: Quantiles must be in the range [0, 1]

2024-08-21 11:10:12,510  | py-experimenter - ERROR    | Traceback (most recent call last):
  File "/home/jonas/Documents/Research/dyad_ranking/torch_plnet/.venv/lib/python3.11/site-packages/py_experimenter/experimenter.py", line 433, in _execute_experiment
    final_status = experiment_function(keyfield_values, result_processor, self.config.custom_configuration.custom_values)
                   ^^^^^^^^^^^^^^^^^^^^^^^^^^^^^^^^^^^^^^^^^^^^^^^^^^^^^^^^^^^^^^^^^^^^^^^^^^^^^^^^^^^^^^^^^^^^^^^^^^^^^^
  File "/home/jonas/Documents/Research/dyad_ranking/torch_plnet/experiments/cp_rank_experimenter.py", line 152, in worker
    predictor.fit(
  File "/home/jonas/Documents/Research/dyad_ranking/torch_plnet/simple_model.py", line 387, in fit
    self.threshold = np.quantile(
                     ^^^^^^^^^^^^
  File "/home/jonas/Documents/Research/dyad_ranking/torch_plnet/.venv/lib/python3.11/site-packages/numpy/lib/function_base.py", line 4542, in quantile
    raise ValueError("Quantiles must be in the range [0, 1]")
ValueError: Quantiles must be in the range [0, 1]

2024-08-21 11:10:12,558  | py-experimenter - ERROR    | Traceback (most recent call last):
  File "/home/jonas/Documents/Research/dyad_ranking/torch_plnet/.venv/lib/python3.11/site-packages/py_experimenter/experimenter.py", line 433, in _execute_experiment
    final_status = experiment_function(keyfield_values, result_processor, self.config.custom_configuration.custom_values)
                   ^^^^^^^^^^^^^^^^^^^^^^^^^^^^^^^^^^^^^^^^^^^^^^^^^^^^^^^^^^^^^^^^^^^^^^^^^^^^^^^^^^^^^^^^^^^^^^^^^^^^^^
  File "/home/jonas/Documents/Research/dyad_ranking/torch_plnet/experiments/cp_rank_experimenter.py", line 152, in worker
    predictor.fit(
  File "/home/jonas/Documents/Research/dyad_ranking/torch_plnet/simple_model.py", line 387, in fit
    self.threshold = np.quantile(
                     ^^^^^^^^^^^^
  File "/home/jonas/Documents/Research/dyad_ranking/torch_plnet/.venv/lib/python3.11/site-packages/numpy/lib/function_base.py", line 4542, in quantile
    raise ValueError("Quantiles must be in the range [0, 1]")
ValueError: Quantiles must be in the range [0, 1]

2024-08-21 11:10:12,574  | py-experimenter - ERROR    | Traceback (most recent call last):
  File "/home/jonas/Documents/Research/dyad_ranking/torch_plnet/.venv/lib/python3.11/site-packages/py_experimenter/experimenter.py", line 433, in _execute_experiment
    final_status = experiment_function(keyfield_values, result_processor, self.config.custom_configuration.custom_values)
                   ^^^^^^^^^^^^^^^^^^^^^^^^^^^^^^^^^^^^^^^^^^^^^^^^^^^^^^^^^^^^^^^^^^^^^^^^^^^^^^^^^^^^^^^^^^^^^^^^^^^^^^
  File "/home/jonas/Documents/Research/dyad_ranking/torch_plnet/experiments/cp_rank_experimenter.py", line 152, in worker
    predictor.fit(
  File "/home/jonas/Documents/Research/dyad_ranking/torch_plnet/simple_model.py", line 387, in fit
    self.threshold = np.quantile(
                     ^^^^^^^^^^^^
  File "/home/jonas/Documents/Research/dyad_ranking/torch_plnet/.venv/lib/python3.11/site-packages/numpy/lib/function_base.py", line 4542, in quantile
    raise ValueError("Quantiles must be in the range [0, 1]")
ValueError: Quantiles must be in the range [0, 1]

2024-08-21 11:10:12,600  | py-experimenter - ERROR    | Traceback (most recent call last):
  File "/home/jonas/Documents/Research/dyad_ranking/torch_plnet/.venv/lib/python3.11/site-packages/py_experimenter/experimenter.py", line 433, in _execute_experiment
    final_status = experiment_function(keyfield_values, result_processor, self.config.custom_configuration.custom_values)
                   ^^^^^^^^^^^^^^^^^^^^^^^^^^^^^^^^^^^^^^^^^^^^^^^^^^^^^^^^^^^^^^^^^^^^^^^^^^^^^^^^^^^^^^^^^^^^^^^^^^^^^^
  File "/home/jonas/Documents/Research/dyad_ranking/torch_plnet/experiments/cp_rank_experimenter.py", line 152, in worker
    predictor.fit(
  File "/home/jonas/Documents/Research/dyad_ranking/torch_plnet/simple_model.py", line 387, in fit
    self.threshold = np.quantile(
                     ^^^^^^^^^^^^
  File "/home/jonas/Documents/Research/dyad_ranking/torch_plnet/.venv/lib/python3.11/site-packages/numpy/lib/function_base.py", line 4542, in quantile
    raise ValueError("Quantiles must be in the range [0, 1]")
ValueError: Quantiles must be in the range [0, 1]

2024-08-21 11:10:12,675  | py-experimenter - ERROR    | Traceback (most recent call last):
  File "/home/jonas/Documents/Research/dyad_ranking/torch_plnet/.venv/lib/python3.11/site-packages/py_experimenter/experimenter.py", line 433, in _execute_experiment
    final_status = experiment_function(keyfield_values, result_processor, self.config.custom_configuration.custom_values)
                   ^^^^^^^^^^^^^^^^^^^^^^^^^^^^^^^^^^^^^^^^^^^^^^^^^^^^^^^^^^^^^^^^^^^^^^^^^^^^^^^^^^^^^^^^^^^^^^^^^^^^^^
  File "/home/jonas/Documents/Research/dyad_ranking/torch_plnet/experiments/cp_rank_experimenter.py", line 152, in worker
    predictor.fit(
  File "/home/jonas/Documents/Research/dyad_ranking/torch_plnet/simple_model.py", line 387, in fit
    self.threshold = np.quantile(
                     ^^^^^^^^^^^^
  File "/home/jonas/Documents/Research/dyad_ranking/torch_plnet/.venv/lib/python3.11/site-packages/numpy/lib/function_base.py", line 4542, in quantile
    raise ValueError("Quantiles must be in the range [0, 1]")
ValueError: Quantiles must be in the range [0, 1]

2024-08-21 11:10:12,732  | py-experimenter - ERROR    | Traceback (most recent call last):
  File "/home/jonas/Documents/Research/dyad_ranking/torch_plnet/.venv/lib/python3.11/site-packages/py_experimenter/experimenter.py", line 433, in _execute_experiment
    final_status = experiment_function(keyfield_values, result_processor, self.config.custom_configuration.custom_values)
                   ^^^^^^^^^^^^^^^^^^^^^^^^^^^^^^^^^^^^^^^^^^^^^^^^^^^^^^^^^^^^^^^^^^^^^^^^^^^^^^^^^^^^^^^^^^^^^^^^^^^^^^
  File "/home/jonas/Documents/Research/dyad_ranking/torch_plnet/experiments/cp_rank_experimenter.py", line 152, in worker
    predictor.fit(
  File "/home/jonas/Documents/Research/dyad_ranking/torch_plnet/simple_model.py", line 387, in fit
    self.threshold = np.quantile(
                     ^^^^^^^^^^^^
  File "/home/jonas/Documents/Research/dyad_ranking/torch_plnet/.venv/lib/python3.11/site-packages/numpy/lib/function_base.py", line 4542, in quantile
    raise ValueError("Quantiles must be in the range [0, 1]")
ValueError: Quantiles must be in the range [0, 1]

2024-08-21 11:10:13,263  | py-experimenter - ERROR    | Traceback (most recent call last):
  File "/home/jonas/Documents/Research/dyad_ranking/torch_plnet/.venv/lib/python3.11/site-packages/py_experimenter/experimenter.py", line 433, in _execute_experiment
    final_status = experiment_function(keyfield_values, result_processor, self.config.custom_configuration.custom_values)
                   ^^^^^^^^^^^^^^^^^^^^^^^^^^^^^^^^^^^^^^^^^^^^^^^^^^^^^^^^^^^^^^^^^^^^^^^^^^^^^^^^^^^^^^^^^^^^^^^^^^^^^^
  File "/home/jonas/Documents/Research/dyad_ranking/torch_plnet/experiments/cp_rank_experimenter.py", line 152, in worker
    predictor.fit(
  File "/home/jonas/Documents/Research/dyad_ranking/torch_plnet/simple_model.py", line 387, in fit
    self.threshold = np.quantile(
                     ^^^^^^^^^^^^
  File "/home/jonas/Documents/Research/dyad_ranking/torch_plnet/.venv/lib/python3.11/site-packages/numpy/lib/function_base.py", line 4542, in quantile
    raise ValueError("Quantiles must be in the range [0, 1]")
ValueError: Quantiles must be in the range [0, 1]

2024-08-21 11:10:16,849  | py-experimenter - ERROR    | Traceback (most recent call last):
  File "/home/jonas/Documents/Research/dyad_ranking/torch_plnet/.venv/lib/python3.11/site-packages/py_experimenter/experimenter.py", line 433, in _execute_experiment
    final_status = experiment_function(keyfield_values, result_processor, self.config.custom_configuration.custom_values)
                   ^^^^^^^^^^^^^^^^^^^^^^^^^^^^^^^^^^^^^^^^^^^^^^^^^^^^^^^^^^^^^^^^^^^^^^^^^^^^^^^^^^^^^^^^^^^^^^^^^^^^^^
  File "/home/jonas/Documents/Research/dyad_ranking/torch_plnet/experiments/cp_rank_experimenter.py", line 152, in worker
    predictor.fit(
  File "/home/jonas/Documents/Research/dyad_ranking/torch_plnet/simple_model.py", line 387, in fit
    self.threshold = np.quantile(
                     ^^^^^^^^^^^^
  File "/home/jonas/Documents/Research/dyad_ranking/torch_plnet/.venv/lib/python3.11/site-packages/numpy/lib/function_base.py", line 4542, in quantile
    raise ValueError("Quantiles must be in the range [0, 1]")
ValueError: Quantiles must be in the range [0, 1]

2024-08-21 11:10:16,916  | py-experimenter - ERROR    | Traceback (most recent call last):
  File "/home/jonas/Documents/Research/dyad_ranking/torch_plnet/.venv/lib/python3.11/site-packages/py_experimenter/experimenter.py", line 433, in _execute_experiment
    final_status = experiment_function(keyfield_values, result_processor, self.config.custom_configuration.custom_values)
                   ^^^^^^^^^^^^^^^^^^^^^^^^^^^^^^^^^^^^^^^^^^^^^^^^^^^^^^^^^^^^^^^^^^^^^^^^^^^^^^^^^^^^^^^^^^^^^^^^^^^^^^
  File "/home/jonas/Documents/Research/dyad_ranking/torch_plnet/experiments/cp_rank_experimenter.py", line 152, in worker
    predictor.fit(
  File "/home/jonas/Documents/Research/dyad_ranking/torch_plnet/simple_model.py", line 387, in fit
    self.threshold = np.quantile(
                     ^^^^^^^^^^^^
  File "/home/jonas/Documents/Research/dyad_ranking/torch_plnet/.venv/lib/python3.11/site-packages/numpy/lib/function_base.py", line 4542, in quantile
    raise ValueError("Quantiles must be in the range [0, 1]")
ValueError: Quantiles must be in the range [0, 1]

2024-08-21 11:10:16,920  | py-experimenter - ERROR    | Traceback (most recent call last):
  File "/home/jonas/Documents/Research/dyad_ranking/torch_plnet/.venv/lib/python3.11/site-packages/py_experimenter/experimenter.py", line 433, in _execute_experiment
    final_status = experiment_function(keyfield_values, result_processor, self.config.custom_configuration.custom_values)
                   ^^^^^^^^^^^^^^^^^^^^^^^^^^^^^^^^^^^^^^^^^^^^^^^^^^^^^^^^^^^^^^^^^^^^^^^^^^^^^^^^^^^^^^^^^^^^^^^^^^^^^^
  File "/home/jonas/Documents/Research/dyad_ranking/torch_plnet/experiments/cp_rank_experimenter.py", line 152, in worker
    predictor.fit(
  File "/home/jonas/Documents/Research/dyad_ranking/torch_plnet/simple_model.py", line 387, in fit
    self.threshold = np.quantile(
                     ^^^^^^^^^^^^
  File "/home/jonas/Documents/Research/dyad_ranking/torch_plnet/.venv/lib/python3.11/site-packages/numpy/lib/function_base.py", line 4542, in quantile
    raise ValueError("Quantiles must be in the range [0, 1]")
ValueError: Quantiles must be in the range [0, 1]

2024-08-21 11:10:16,930  | py-experimenter - ERROR    | Traceback (most recent call last):
  File "/home/jonas/Documents/Research/dyad_ranking/torch_plnet/.venv/lib/python3.11/site-packages/py_experimenter/experimenter.py", line 433, in _execute_experiment
    final_status = experiment_function(keyfield_values, result_processor, self.config.custom_configuration.custom_values)
                   ^^^^^^^^^^^^^^^^^^^^^^^^^^^^^^^^^^^^^^^^^^^^^^^^^^^^^^^^^^^^^^^^^^^^^^^^^^^^^^^^^^^^^^^^^^^^^^^^^^^^^^
  File "/home/jonas/Documents/Research/dyad_ranking/torch_plnet/experiments/cp_rank_experimenter.py", line 152, in worker
    predictor.fit(
  File "/home/jonas/Documents/Research/dyad_ranking/torch_plnet/simple_model.py", line 387, in fit
    self.threshold = np.quantile(
                     ^^^^^^^^^^^^
  File "/home/jonas/Documents/Research/dyad_ranking/torch_plnet/.venv/lib/python3.11/site-packages/numpy/lib/function_base.py", line 4542, in quantile
    raise ValueError("Quantiles must be in the range [0, 1]")
ValueError: Quantiles must be in the range [0, 1]

2024-08-21 11:10:17,167  | py-experimenter - ERROR    | Traceback (most recent call last):
  File "/home/jonas/Documents/Research/dyad_ranking/torch_plnet/.venv/lib/python3.11/site-packages/py_experimenter/experimenter.py", line 433, in _execute_experiment
    final_status = experiment_function(keyfield_values, result_processor, self.config.custom_configuration.custom_values)
                   ^^^^^^^^^^^^^^^^^^^^^^^^^^^^^^^^^^^^^^^^^^^^^^^^^^^^^^^^^^^^^^^^^^^^^^^^^^^^^^^^^^^^^^^^^^^^^^^^^^^^^^
  File "/home/jonas/Documents/Research/dyad_ranking/torch_plnet/experiments/cp_rank_experimenter.py", line 152, in worker
    predictor.fit(
  File "/home/jonas/Documents/Research/dyad_ranking/torch_plnet/simple_model.py", line 387, in fit
    self.threshold = np.quantile(
                     ^^^^^^^^^^^^
  File "/home/jonas/Documents/Research/dyad_ranking/torch_plnet/.venv/lib/python3.11/site-packages/numpy/lib/function_base.py", line 4542, in quantile
    raise ValueError("Quantiles must be in the range [0, 1]")
ValueError: Quantiles must be in the range [0, 1]

2024-08-21 11:10:17,182  | py-experimenter - ERROR    | Traceback (most recent call last):
  File "/home/jonas/Documents/Research/dyad_ranking/torch_plnet/.venv/lib/python3.11/site-packages/py_experimenter/experimenter.py", line 433, in _execute_experiment
    final_status = experiment_function(keyfield_values, result_processor, self.config.custom_configuration.custom_values)
                   ^^^^^^^^^^^^^^^^^^^^^^^^^^^^^^^^^^^^^^^^^^^^^^^^^^^^^^^^^^^^^^^^^^^^^^^^^^^^^^^^^^^^^^^^^^^^^^^^^^^^^^
  File "/home/jonas/Documents/Research/dyad_ranking/torch_plnet/experiments/cp_rank_experimenter.py", line 152, in worker
    predictor.fit(
  File "/home/jonas/Documents/Research/dyad_ranking/torch_plnet/simple_model.py", line 387, in fit
    self.threshold = np.quantile(
                     ^^^^^^^^^^^^
  File "/home/jonas/Documents/Research/dyad_ranking/torch_plnet/.venv/lib/python3.11/site-packages/numpy/lib/function_base.py", line 4542, in quantile
    raise ValueError("Quantiles must be in the range [0, 1]")
ValueError: Quantiles must be in the range [0, 1]

2024-08-21 11:10:17,223  | py-experimenter - ERROR    | Traceback (most recent call last):
  File "/home/jonas/Documents/Research/dyad_ranking/torch_plnet/.venv/lib/python3.11/site-packages/py_experimenter/experimenter.py", line 433, in _execute_experiment
    final_status = experiment_function(keyfield_values, result_processor, self.config.custom_configuration.custom_values)
                   ^^^^^^^^^^^^^^^^^^^^^^^^^^^^^^^^^^^^^^^^^^^^^^^^^^^^^^^^^^^^^^^^^^^^^^^^^^^^^^^^^^^^^^^^^^^^^^^^^^^^^^
  File "/home/jonas/Documents/Research/dyad_ranking/torch_plnet/experiments/cp_rank_experimenter.py", line 152, in worker
    predictor.fit(
  File "/home/jonas/Documents/Research/dyad_ranking/torch_plnet/simple_model.py", line 387, in fit
    self.threshold = np.quantile(
                     ^^^^^^^^^^^^
  File "/home/jonas/Documents/Research/dyad_ranking/torch_plnet/.venv/lib/python3.11/site-packages/numpy/lib/function_base.py", line 4542, in quantile
    raise ValueError("Quantiles must be in the range [0, 1]")
ValueError: Quantiles must be in the range [0, 1]

2024-08-21 11:10:17,257  | py-experimenter - ERROR    | Traceback (most recent call last):
  File "/home/jonas/Documents/Research/dyad_ranking/torch_plnet/.venv/lib/python3.11/site-packages/py_experimenter/experimenter.py", line 433, in _execute_experiment
    final_status = experiment_function(keyfield_values, result_processor, self.config.custom_configuration.custom_values)
                   ^^^^^^^^^^^^^^^^^^^^^^^^^^^^^^^^^^^^^^^^^^^^^^^^^^^^^^^^^^^^^^^^^^^^^^^^^^^^^^^^^^^^^^^^^^^^^^^^^^^^^^
  File "/home/jonas/Documents/Research/dyad_ranking/torch_plnet/experiments/cp_rank_experimenter.py", line 152, in worker
    predictor.fit(
  File "/home/jonas/Documents/Research/dyad_ranking/torch_plnet/simple_model.py", line 387, in fit
    self.threshold = np.quantile(
                     ^^^^^^^^^^^^
  File "/home/jonas/Documents/Research/dyad_ranking/torch_plnet/.venv/lib/python3.11/site-packages/numpy/lib/function_base.py", line 4542, in quantile
    raise ValueError("Quantiles must be in the range [0, 1]")
ValueError: Quantiles must be in the range [0, 1]

2024-08-21 11:10:17,283  | py-experimenter - ERROR    | Traceback (most recent call last):
  File "/home/jonas/Documents/Research/dyad_ranking/torch_plnet/.venv/lib/python3.11/site-packages/py_experimenter/experimenter.py", line 433, in _execute_experiment
    final_status = experiment_function(keyfield_values, result_processor, self.config.custom_configuration.custom_values)
                   ^^^^^^^^^^^^^^^^^^^^^^^^^^^^^^^^^^^^^^^^^^^^^^^^^^^^^^^^^^^^^^^^^^^^^^^^^^^^^^^^^^^^^^^^^^^^^^^^^^^^^^
  File "/home/jonas/Documents/Research/dyad_ranking/torch_plnet/experiments/cp_rank_experimenter.py", line 152, in worker
    predictor.fit(
  File "/home/jonas/Documents/Research/dyad_ranking/torch_plnet/simple_model.py", line 387, in fit
    self.threshold = np.quantile(
                     ^^^^^^^^^^^^
  File "/home/jonas/Documents/Research/dyad_ranking/torch_plnet/.venv/lib/python3.11/site-packages/numpy/lib/function_base.py", line 4542, in quantile
    raise ValueError("Quantiles must be in the range [0, 1]")
ValueError: Quantiles must be in the range [0, 1]

2024-08-21 11:10:17,372  | py-experimenter - ERROR    | Traceback (most recent call last):
  File "/home/jonas/Documents/Research/dyad_ranking/torch_plnet/.venv/lib/python3.11/site-packages/py_experimenter/experimenter.py", line 433, in _execute_experiment
    final_status = experiment_function(keyfield_values, result_processor, self.config.custom_configuration.custom_values)
                   ^^^^^^^^^^^^^^^^^^^^^^^^^^^^^^^^^^^^^^^^^^^^^^^^^^^^^^^^^^^^^^^^^^^^^^^^^^^^^^^^^^^^^^^^^^^^^^^^^^^^^^
  File "/home/jonas/Documents/Research/dyad_ranking/torch_plnet/experiments/cp_rank_experimenter.py", line 152, in worker
    predictor.fit(
  File "/home/jonas/Documents/Research/dyad_ranking/torch_plnet/simple_model.py", line 387, in fit
    self.threshold = np.quantile(
                     ^^^^^^^^^^^^
  File "/home/jonas/Documents/Research/dyad_ranking/torch_plnet/.venv/lib/python3.11/site-packages/numpy/lib/function_base.py", line 4542, in quantile
    raise ValueError("Quantiles must be in the range [0, 1]")
ValueError: Quantiles must be in the range [0, 1]

2024-08-21 11:10:17,415  | py-experimenter - ERROR    | Traceback (most recent call last):
  File "/home/jonas/Documents/Research/dyad_ranking/torch_plnet/.venv/lib/python3.11/site-packages/py_experimenter/experimenter.py", line 433, in _execute_experiment
    final_status = experiment_function(keyfield_values, result_processor, self.config.custom_configuration.custom_values)
                   ^^^^^^^^^^^^^^^^^^^^^^^^^^^^^^^^^^^^^^^^^^^^^^^^^^^^^^^^^^^^^^^^^^^^^^^^^^^^^^^^^^^^^^^^^^^^^^^^^^^^^^
  File "/home/jonas/Documents/Research/dyad_ranking/torch_plnet/experiments/cp_rank_experimenter.py", line 152, in worker
    predictor.fit(
  File "/home/jonas/Documents/Research/dyad_ranking/torch_plnet/simple_model.py", line 387, in fit
    self.threshold = np.quantile(
                     ^^^^^^^^^^^^
  File "/home/jonas/Documents/Research/dyad_ranking/torch_plnet/.venv/lib/python3.11/site-packages/numpy/lib/function_base.py", line 4542, in quantile
    raise ValueError("Quantiles must be in the range [0, 1]")
ValueError: Quantiles must be in the range [0, 1]

2024-08-21 11:10:17,514  | py-experimenter - ERROR    | Traceback (most recent call last):
  File "/home/jonas/Documents/Research/dyad_ranking/torch_plnet/.venv/lib/python3.11/site-packages/py_experimenter/experimenter.py", line 433, in _execute_experiment
    final_status = experiment_function(keyfield_values, result_processor, self.config.custom_configuration.custom_values)
                   ^^^^^^^^^^^^^^^^^^^^^^^^^^^^^^^^^^^^^^^^^^^^^^^^^^^^^^^^^^^^^^^^^^^^^^^^^^^^^^^^^^^^^^^^^^^^^^^^^^^^^^
  File "/home/jonas/Documents/Research/dyad_ranking/torch_plnet/experiments/cp_rank_experimenter.py", line 152, in worker
    predictor.fit(
  File "/home/jonas/Documents/Research/dyad_ranking/torch_plnet/simple_model.py", line 387, in fit
    self.threshold = np.quantile(
                     ^^^^^^^^^^^^
  File "/home/jonas/Documents/Research/dyad_ranking/torch_plnet/.venv/lib/python3.11/site-packages/numpy/lib/function_base.py", line 4542, in quantile
    raise ValueError("Quantiles must be in the range [0, 1]")
ValueError: Quantiles must be in the range [0, 1]

2024-10-17 13:18:10,364  | py-experimenter - INFO     | Found 5 keyfields
2024-10-17 13:18:10,365  | py-experimenter - INFO     | Found 9 resultfields
2024-10-17 13:18:10,365  | py-experimenter - WARNING  | No logtables given
2024-10-17 13:18:10,365  | py-experimenter - WARNING  | No custom section defined in config
2024-10-17 13:18:10,365  | py-experimenter - WARNING  | No codecarbon section defined in config
2024-10-17 13:18:38,194  | py-experimenter - INFO     | Found 5 keyfields
2024-10-17 13:18:38,194  | py-experimenter - INFO     | Found 9 resultfields
2024-10-17 13:18:38,194  | py-experimenter - WARNING  | No logtables given
2024-10-17 13:18:38,194  | py-experimenter - WARNING  | No custom section defined in config
2024-10-17 13:18:38,194  | py-experimenter - WARNING  | No codecarbon section defined in config
2024-10-17 13:18:38,204  | py-experimenter - INFO     | Initialized and connected to database
2024-10-17 13:18:38,223  | py-experimenter - INFO     | 240 rows successfully added to database. 120 rows were skipped.
2024-10-17 13:18:43,296  | py-experimenter - INFO     | All configured executions finished.
2024-10-17 13:20:10,707  | py-experimenter - INFO     | Found 5 keyfields
2024-10-17 13:20:10,707  | py-experimenter - INFO     | Found 9 resultfields
2024-10-17 13:20:10,708  | py-experimenter - WARNING  | No logtables given
2024-10-17 13:20:10,708  | py-experimenter - WARNING  | No custom section defined in config
2024-10-17 13:20:10,708  | py-experimenter - WARNING  | No codecarbon section defined in config
2024-10-17 13:20:10,708  | py-experimenter - INFO     | Initialized and connected to database
2024-10-17 13:20:10,735  | py-experimenter - INFO     | 60 rows successfully added to database. 0 rows were skipped.
2024-10-17 13:20:16,181  | py-experimenter - INFO     | All configured executions finished.
2024-10-17 13:21:02,995  | py-experimenter - INFO     | Found 5 keyfields
2024-10-17 13:21:02,996  | py-experimenter - INFO     | Found 9 resultfields
2024-10-17 13:21:02,996  | py-experimenter - WARNING  | No logtables given
2024-10-17 13:21:02,996  | py-experimenter - WARNING  | No custom section defined in config
2024-10-17 13:21:02,996  | py-experimenter - WARNING  | No codecarbon section defined in config
2024-10-17 13:21:02,996  | py-experimenter - INFO     | Initialized and connected to database
2024-10-17 13:21:03,058  | py-experimenter - INFO     | 60 rows successfully added to database. 0 rows were skipped.
2024-10-17 13:21:22,822  | py-experimenter - INFO     | All configured executions finished.
2024-10-17 13:24:00,994  | py-experimenter - INFO     | Found 5 keyfields
2024-10-17 13:24:00,994  | py-experimenter - INFO     | Found 9 resultfields
2024-10-17 13:24:00,994  | py-experimenter - WARNING  | No logtables given
2024-10-17 13:24:00,994  | py-experimenter - WARNING  | No custom section defined in config
2024-10-17 13:24:00,994  | py-experimenter - WARNING  | No codecarbon section defined in config
2024-10-17 13:24:00,994  | py-experimenter - INFO     | Initialized and connected to database
2024-10-17 13:24:00,995  | py-experimenter - INFO     | No rows to add. All the 60 experiments already exist.
2024-10-17 13:24:15,216  | py-experimenter - INFO     | All configured executions finished.
2024-10-17 13:31:53,838  | py-experimenter - INFO     | Found 5 keyfields
2024-10-17 13:31:53,838  | py-experimenter - INFO     | Found 9 resultfields
2024-10-17 13:31:53,838  | py-experimenter - WARNING  | No logtables given
2024-10-17 13:31:53,838  | py-experimenter - WARNING  | No custom section defined in config
2024-10-17 13:31:53,838  | py-experimenter - WARNING  | No codecarbon section defined in config
2024-10-17 13:31:53,838  | py-experimenter - INFO     | Initialized and connected to database
2024-10-17 13:31:53,839  | py-experimenter - INFO     | No rows to add. All the 60 experiments already exist.
2024-10-17 13:32:06,929  | py-experimenter - INFO     | All configured executions finished.
2024-10-17 13:34:05,590  | py-experimenter - INFO     | Found 5 keyfields
2024-10-17 13:34:05,591  | py-experimenter - INFO     | Found 9 resultfields
2024-10-17 13:34:05,591  | py-experimenter - WARNING  | No logtables given
2024-10-17 13:34:05,591  | py-experimenter - WARNING  | No custom section defined in config
2024-10-17 13:34:05,591  | py-experimenter - WARNING  | No codecarbon section defined in config
2024-10-17 13:34:05,591  | py-experimenter - INFO     | Initialized and connected to database
2024-10-17 13:34:05,592  | py-experimenter - INFO     | No rows to add. All the 60 experiments already exist.
2024-10-17 13:38:39,803  | py-experimenter - INFO     | All configured executions finished.
2024-10-17 13:42:57,342  | py-experimenter - INFO     | Found 5 keyfields
2024-10-17 13:42:57,343  | py-experimenter - INFO     | Found 9 resultfields
2024-10-17 13:42:57,343  | py-experimenter - WARNING  | No logtables given
2024-10-17 13:42:57,343  | py-experimenter - WARNING  | No custom section defined in config
2024-10-17 13:42:57,343  | py-experimenter - WARNING  | No codecarbon section defined in config
2024-10-17 13:42:57,343  | py-experimenter - INFO     | Initialized and connected to database
2024-10-17 13:42:57,344  | py-experimenter - INFO     | No rows to add. All the 60 experiments already exist.
2024-10-17 13:46:52,238  | py-experimenter - INFO     | All configured executions finished.
2024-11-14 18:18:50,499  | py-experimenter - INFO     | Found 5 keyfields
2024-11-14 18:18:50,499  | py-experimenter - INFO     | Found 10 resultfields
2024-11-14 18:18:50,499  | py-experimenter - WARNING  | No logtables given
2024-11-14 18:18:50,499  | py-experimenter - WARNING  | No custom section defined in config
2024-11-14 18:18:50,499  | py-experimenter - WARNING  | No codecarbon section defined in config
2024-11-14 18:18:50,500  | py-experimenter - INFO     | Initialized and connected to database
2024-11-14 18:18:50,542  | py-experimenter - INFO     | 4 rows successfully added to database. 0 rows were skipped.
2024-11-14 18:18:54,920  | py-experimenter - ERROR    | Traceback (most recent call last):
  File "/home/jonas/Documents/Research/dyad_ranking/torch_plnet/.venv/lib/python3.11/site-packages/py_experimenter/experimenter.py", line 433, in _execute_experiment
    final_status = experiment_function(keyfield_values, result_processor, self.config.custom_configuration.custom_values)
                   ^^^^^^^^^^^^^^^^^^^^^^^^^^^^^^^^^^^^^^^^^^^^^^^^^^^^^^^^^^^^^^^^^^^^^^^^^^^^^^^^^^^^^^^^^^^^^^^^^^^^^^
  File "/home/jonas/Documents/Research/dyad_ranking/torch_plnet/experiments/cp_rank_experimenter.py", line 179, in worker
    num_classes=num_classes, alpha=alpha, hidden_dim=16
                                   ^^^^^
NameError: name 'alpha' is not defined

2024-11-14 18:18:59,252  | py-experimenter - ERROR    | Traceback (most recent call last):
  File "/home/jonas/Documents/Research/dyad_ranking/torch_plnet/.venv/lib/python3.11/site-packages/py_experimenter/experimenter.py", line 433, in _execute_experiment
    final_status = experiment_function(keyfield_values, result_processor, self.config.custom_configuration.custom_values)
                   ^^^^^^^^^^^^^^^^^^^^^^^^^^^^^^^^^^^^^^^^^^^^^^^^^^^^^^^^^^^^^^^^^^^^^^^^^^^^^^^^^^^^^^^^^^^^^^^^^^^^^^
  File "/home/jonas/Documents/Research/dyad_ranking/torch_plnet/experiments/cp_rank_experimenter.py", line 163, in worker
    predictor = ConformalPredictor(model=model, alpha=alpha)
                                                      ^^^^^
NameError: name 'alpha' is not defined

2024-11-14 18:19:03,620  | py-experimenter - ERROR    | Traceback (most recent call last):
  File "/home/jonas/Documents/Research/dyad_ranking/torch_plnet/.venv/lib/python3.11/site-packages/py_experimenter/experimenter.py", line 433, in _execute_experiment
    final_status = experiment_function(keyfield_values, result_processor, self.config.custom_configuration.custom_values)
                   ^^^^^^^^^^^^^^^^^^^^^^^^^^^^^^^^^^^^^^^^^^^^^^^^^^^^^^^^^^^^^^^^^^^^^^^^^^^^^^^^^^^^^^^^^^^^^^^^^^^^^^
  File "/home/jonas/Documents/Research/dyad_ranking/torch_plnet/experiments/cp_rank_experimenter.py", line 150, in worker
    predictor = ConformalPredictor(model=model, alpha=alpha)
                                                      ^^^^^
NameError: name 'alpha' is not defined

2024-11-14 18:19:07,952  | py-experimenter - ERROR    | Traceback (most recent call last):
  File "/home/jonas/Documents/Research/dyad_ranking/torch_plnet/.venv/lib/python3.11/site-packages/py_experimenter/experimenter.py", line 433, in _execute_experiment
    final_status = experiment_function(keyfield_values, result_processor, self.config.custom_configuration.custom_values)
                   ^^^^^^^^^^^^^^^^^^^^^^^^^^^^^^^^^^^^^^^^^^^^^^^^^^^^^^^^^^^^^^^^^^^^^^^^^^^^^^^^^^^^^^^^^^^^^^^^^^^^^^
  File "/home/jonas/Documents/Research/dyad_ranking/torch_plnet/experiments/cp_rank_experimenter.py", line 200, in worker
    effective_length = (1 - cal_size) * len(X_train)
                        ~~^~~~~~~~~~
TypeError: unsupported operand type(s) for -: 'int' and 'tuple'

2024-11-14 18:19:07,995  | py-experimenter - INFO     | All configured executions finished.
2024-11-14 18:20:27,320  | py-experimenter - INFO     | Found 5 keyfields
2024-11-14 18:20:27,320  | py-experimenter - INFO     | Found 10 resultfields
2024-11-14 18:20:27,320  | py-experimenter - WARNING  | No logtables given
2024-11-14 18:20:27,320  | py-experimenter - WARNING  | No custom section defined in config
2024-11-14 18:20:27,321  | py-experimenter - WARNING  | No codecarbon section defined in config
2024-11-14 18:20:27,321  | py-experimenter - INFO     | Initialized and connected to database
2024-11-14 18:20:27,372  | py-experimenter - INFO     | 4 rows successfully added to database. 0 rows were skipped.
2024-11-14 18:20:31,709  | py-experimenter - ERROR    | Traceback (most recent call last):
  File "/home/jonas/Documents/Research/dyad_ranking/torch_plnet/.venv/lib/python3.11/site-packages/py_experimenter/experimenter.py", line 433, in _execute_experiment
    final_status = experiment_function(keyfield_values, result_processor, self.config.custom_configuration.custom_values)
                   ^^^^^^^^^^^^^^^^^^^^^^^^^^^^^^^^^^^^^^^^^^^^^^^^^^^^^^^^^^^^^^^^^^^^^^^^^^^^^^^^^^^^^^^^^^^^^^^^^^^^^^
  File "/home/jonas/Documents/Research/dyad_ranking/torch_plnet/experiments/cp_rank_experimenter.py", line 181, in worker
    effective_length = (1 - cal_size) * len(X_train)
                        ~~^~~~~~~~~~
TypeError: unsupported operand type(s) for -: 'int' and 'tuple'

2024-11-14 18:20:36,137  | py-experimenter - ERROR    | Traceback (most recent call last):
  File "/home/jonas/Documents/Research/dyad_ranking/torch_plnet/.venv/lib/python3.11/site-packages/py_experimenter/experimenter.py", line 433, in _execute_experiment
    final_status = experiment_function(keyfield_values, result_processor, self.config.custom_configuration.custom_values)
                   ^^^^^^^^^^^^^^^^^^^^^^^^^^^^^^^^^^^^^^^^^^^^^^^^^^^^^^^^^^^^^^^^^^^^^^^^^^^^^^^^^^^^^^^^^^^^^^^^^^^^^^
  File "/home/jonas/Documents/Research/dyad_ranking/torch_plnet/experiments/cp_rank_experimenter.py", line 164, in worker
    predictor.fit(
  File "/home/jonas/Documents/Research/dyad_ranking/torch_plnet/simple_model.py", line 474, in fit
    X_train, X_cal, y_train, y_cal = train_test_split(
                                     ^^^^^^^^^^^^^^^^^
  File "/home/jonas/Documents/Research/dyad_ranking/torch_plnet/.venv/lib/python3.11/site-packages/sklearn/utils/_param_validation.py", line 203, in wrapper
    validate_parameter_constraints(
  File "/home/jonas/Documents/Research/dyad_ranking/torch_plnet/.venv/lib/python3.11/site-packages/sklearn/utils/_param_validation.py", line 95, in validate_parameter_constraints
    raise InvalidParameterError(
sklearn.utils._param_validation.InvalidParameterError: The 'test_size' parameter of train_test_split must be a float in the range (0.0, 1.0), an int in the range [1, inf) or None. Got (0.2,) instead.

2024-11-14 18:20:45,059  | py-experimenter - ERROR    | Traceback (most recent call last):
  File "/home/jonas/Documents/Research/dyad_ranking/torch_plnet/.venv/lib/python3.11/site-packages/py_experimenter/experimenter.py", line 433, in _execute_experiment
    final_status = experiment_function(keyfield_values, result_processor, self.config.custom_configuration.custom_values)
                   ^^^^^^^^^^^^^^^^^^^^^^^^^^^^^^^^^^^^^^^^^^^^^^^^^^^^^^^^^^^^^^^^^^^^^^^^^^^^^^^^^^^^^^^^^^^^^^^^^^^^^^
  File "/home/jonas/Documents/Research/dyad_ranking/torch_plnet/experiments/cp_rank_experimenter.py", line 200, in worker
    effective_length = (1 - cal_size) * len(X_train)
                        ~~^~~~~~~~~~
TypeError: unsupported operand type(s) for -: 'int' and 'tuple'

2024-11-14 18:20:45,113  | py-experimenter - INFO     | All configured executions finished.
2024-11-14 18:33:02,890  | py-experimenter - INFO     | Found 5 keyfields
2024-11-14 18:33:02,890  | py-experimenter - INFO     | Found 10 resultfields
2024-11-14 18:33:02,890  | py-experimenter - WARNING  | No logtables given
2024-11-14 18:33:02,890  | py-experimenter - WARNING  | No custom section defined in config
2024-11-14 18:33:02,890  | py-experimenter - WARNING  | No codecarbon section defined in config
2024-11-14 18:33:02,890  | py-experimenter - INFO     | Initialized and connected to database
2024-11-14 18:33:02,932  | py-experimenter - INFO     | 4 rows successfully added to database. 0 rows were skipped.
2024-11-14 18:33:21,429  | py-experimenter - INFO     | All configured executions finished.
2024-11-14 18:38:42,680  | py-experimenter - INFO     | Found 5 keyfields
2024-11-14 18:38:42,681  | py-experimenter - INFO     | Found 10 resultfields
2024-11-14 18:38:42,681  | py-experimenter - WARNING  | No logtables given
2024-11-14 18:38:42,681  | py-experimenter - WARNING  | No custom section defined in config
2024-11-14 18:38:42,681  | py-experimenter - WARNING  | No codecarbon section defined in config
2024-11-14 18:38:42,681  | py-experimenter - INFO     | Initialized and connected to database
2024-11-14 18:38:42,751  | py-experimenter - INFO     | 960 rows successfully added to database. 0 rows were skipped.
2024-11-14 18:40:00,356  | py-experimenter - INFO     | Found 5 keyfields
2024-11-14 18:40:00,356  | py-experimenter - INFO     | Found 10 resultfields
2024-11-14 18:40:00,356  | py-experimenter - WARNING  | No logtables given
2024-11-14 18:40:00,356  | py-experimenter - WARNING  | No custom section defined in config
2024-11-14 18:40:00,356  | py-experimenter - WARNING  | No codecarbon section defined in config
2024-11-14 18:40:00,356  | py-experimenter - INFO     | Initialized and connected to database
2024-11-14 18:40:00,423  | py-experimenter - INFO     | 960 rows successfully added to database. 0 rows were skipped.
2024-11-14 19:25:44,737  | py-experimenter - INFO     | Found 5 keyfields
2024-11-14 19:25:44,737  | py-experimenter - INFO     | Found 10 resultfields
2024-11-14 19:25:44,737  | py-experimenter - WARNING  | No logtables given
2024-11-14 19:25:44,737  | py-experimenter - WARNING  | No custom section defined in config
2024-11-14 19:25:44,737  | py-experimenter - WARNING  | No codecarbon section defined in config
2024-11-14 19:25:44,737  | py-experimenter - INFO     | Initialized and connected to database
2024-11-14 19:25:44,784  | py-experimenter - INFO     | 96 rows successfully added to database. 0 rows were skipped.
2024-11-14 21:06:20,427  | py-experimenter - INFO     | All configured executions finished.
2024-11-14 22:39:30,745  | py-experimenter - INFO     | Found 5 keyfields
2024-11-14 22:39:30,745  | py-experimenter - INFO     | Found 10 resultfields
2024-11-14 22:39:30,745  | py-experimenter - WARNING  | No logtables given
2024-11-14 22:39:30,745  | py-experimenter - WARNING  | No custom section defined in config
2024-11-14 22:39:30,745  | py-experimenter - WARNING  | No codecarbon section defined in config
2024-11-14 22:39:30,746  | py-experimenter - INFO     | Initialized and connected to database
2024-11-14 22:39:30,783  | py-experimenter - INFO     | 1104 rows successfully added to database. 96 rows were skipped.
2025-01-25 23:15:54,111  | py-experimenter - INFO     | Found 4 keyfields
2025-01-25 23:15:54,112  | py-experimenter - INFO     | Found 2 resultfields
2025-01-25 23:15:54,112  | py-experimenter - INFO     | Found 1 logtables
2025-01-25 23:15:54,113  | py-experimenter - INFO     | Found logtable cp_rank_dev__new_cross__results
2025-01-25 23:15:54,113  | py-experimenter - WARNING  | No custom section defined in config
2025-01-25 23:15:54,113  | py-experimenter - WARNING  | No codecarbon section defined in config
2025-01-25 23:15:54,113  | py-experimenter - INFO     | Initialized and connected to database
2025-01-25 23:15:54,166  | py-experimenter - INFO     | 1 rows successfully added to database. 0 rows were skipped.
2025-01-25 23:16:06,807  | py-experimenter - ERROR    | Traceback (most recent call last):
  File "/home/jonas/anaconda3/envs/plnet/lib/python3.11/site-packages/py_experimenter/experimenter.py", line 433, in _execute_experiment
    final_status = experiment_function(keyfield_values, result_processor, self.config.custom_configuration.custom_values)
                   ^^^^^^^^^^^^^^^^^^^^^^^^^^^^^^^^^^^^^^^^^^^^^^^^^^^^^^^^^^^^^^^^^^^^^^^^^^^^^^^^^^^^^^^^^^^^^^^^^^^^^^
  File "/home/jonas/Documents/Research/torch_plnet/experiments/simple_experiment_torchcp.py", line 237, in worker
    conformity_scores = [APS(), THR(), TOPK(), RAPS(), SAPS(), Margin(), KNN()]
                                                                         ^^^^^
TypeError: KNN.__init__() missing 3 required positional arguments: 'features', 'labels', and 'num_classes'

2025-01-25 23:16:06,936  | py-experimenter - INFO     | All configured executions finished.
2025-01-25 23:16:36,645  | py-experimenter - INFO     | Found 4 keyfields
2025-01-25 23:16:36,645  | py-experimenter - INFO     | Found 2 resultfields
2025-01-25 23:16:36,646  | py-experimenter - INFO     | Found 1 logtables
2025-01-25 23:16:36,646  | py-experimenter - INFO     | Found logtable cp_rank_dev__new_cross__results
2025-01-25 23:16:36,646  | py-experimenter - WARNING  | No custom section defined in config
2025-01-25 23:16:36,646  | py-experimenter - WARNING  | No codecarbon section defined in config
2025-01-25 23:16:36,647  | py-experimenter - INFO     | Initialized and connected to database
2025-01-25 23:16:36,648  | py-experimenter - INFO     | No rows to add. All the 1 experiments already exist.
2025-01-25 23:16:37,227  | py-experimenter - INFO     | All configured executions finished.
2025-01-25 23:17:07,379  | py-experimenter - INFO     | Found 4 keyfields
2025-01-25 23:17:07,379  | py-experimenter - INFO     | Found 2 resultfields
2025-01-25 23:17:07,379  | py-experimenter - INFO     | Found 1 logtables
2025-01-25 23:17:07,379  | py-experimenter - INFO     | Found logtable cp_rank_dev__new_cross__results
2025-01-25 23:17:07,379  | py-experimenter - WARNING  | No custom section defined in config
2025-01-25 23:17:07,379  | py-experimenter - WARNING  | No codecarbon section defined in config
2025-01-25 23:17:07,380  | py-experimenter - INFO     | Initialized and connected to database
2025-01-25 23:17:07,440  | py-experimenter - INFO     | 1 rows successfully added to database. 0 rows were skipped.
2025-01-25 23:17:19,157  | py-experimenter - INFO     | All configured executions finished.
2025-01-26 00:29:10,450  | py-experimenter - INFO     | Found 4 keyfields
2025-01-26 00:29:10,451  | py-experimenter - INFO     | Found 2 resultfields
2025-01-26 00:29:10,451  | py-experimenter - INFO     | Found 1 logtables
2025-01-26 00:29:10,451  | py-experimenter - INFO     | Found logtable cp_rank_dev__new_cross__results
2025-01-26 00:29:10,451  | py-experimenter - WARNING  | No custom section defined in config
2025-01-26 00:29:10,451  | py-experimenter - WARNING  | No codecarbon section defined in config
2025-01-26 00:29:10,452  | py-experimenter - INFO     | Initialized and connected to database
2025-01-26 00:29:10,510  | py-experimenter - INFO     | 1 rows successfully added to database. 0 rows were skipped.
2025-01-26 00:29:20,965  | py-experimenter - ERROR    | Traceback (most recent call last):
  File "/home/jonas/anaconda3/envs/plnet/lib/python3.11/site-packages/py_experimenter/experimenter.py", line 433, in _execute_experiment
    final_status = experiment_function(keyfield_values, result_processor, self.config.custom_configuration.custom_values)
                   ^^^^^^^^^^^^^^^^^^^^^^^^^^^^^^^^^^^^^^^^^^^^^^^^^^^^^^^^^^^^^^^^^^^^^^^^^^^^^^^^^^^^^^^^^^^^^^^^^^^^^^
  File "/home/jonas/Documents/Research/torch_plnet/experiments/simple_experiment_torchcp.py", line 259, in worker
    inputs = batch[0].to(torch.get_default_device())
                         ^^^^^^^^^^^^^^^^^^^^^^^^
  File "/home/jonas/anaconda3/envs/plnet/lib/python3.11/site-packages/torch/__init__.py", line 1938, in __getattr__
    raise AttributeError(f"module '{__name__}' has no attribute '{name}'")
AttributeError: module 'torch' has no attribute 'get_default_device'

2025-01-26 00:29:21,066  | py-experimenter - INFO     | All configured executions finished.
2025-01-26 00:29:59,670  | py-experimenter - INFO     | Found 4 keyfields
2025-01-26 00:29:59,671  | py-experimenter - INFO     | Found 2 resultfields
2025-01-26 00:29:59,671  | py-experimenter - INFO     | Found 1 logtables
2025-01-26 00:29:59,671  | py-experimenter - INFO     | Found logtable cp_rank_dev__new_cross__results
2025-01-26 00:29:59,671  | py-experimenter - WARNING  | No custom section defined in config
2025-01-26 00:29:59,671  | py-experimenter - WARNING  | No codecarbon section defined in config
2025-01-26 00:29:59,671  | py-experimenter - INFO     | Initialized and connected to database
2025-01-26 00:29:59,672  | py-experimenter - INFO     | No rows to add. All the 1 experiments already exist.
2025-01-26 00:30:00,148  | py-experimenter - INFO     | All configured executions finished.
2025-01-26 00:30:13,771  | py-experimenter - INFO     | Found 4 keyfields
2025-01-26 00:30:13,772  | py-experimenter - INFO     | Found 2 resultfields
2025-01-26 00:30:13,772  | py-experimenter - INFO     | Found 1 logtables
2025-01-26 00:30:13,772  | py-experimenter - INFO     | Found logtable cp_rank_dev__new_cross__results
2025-01-26 00:30:13,772  | py-experimenter - WARNING  | No custom section defined in config
2025-01-26 00:30:13,772  | py-experimenter - WARNING  | No codecarbon section defined in config
2025-01-26 00:30:13,772  | py-experimenter - INFO     | Initialized and connected to database
2025-01-26 00:30:13,830  | py-experimenter - INFO     | 1 rows successfully added to database. 0 rows were skipped.
2025-01-26 00:30:21,478  | py-experimenter - ERROR    | Traceback (most recent call last):
  File "/home/jonas/anaconda3/envs/plnet/lib/python3.11/site-packages/py_experimenter/experimenter.py", line 433, in _execute_experiment
    final_status = experiment_function(keyfield_values, result_processor, self.config.custom_configuration.custom_values)
                   ^^^^^^^^^^^^^^^^^^^^^^^^^^^^^^^^^^^^^^^^^^^^^^^^^^^^^^^^^^^^^^^^^^^^^^^^^^^^^^^^^^^^^^^^^^^^^^^^^^^^^^
  File "/home/jonas/Documents/Research/torch_plnet/experiments/simple_experiment_torchcp.py", line 291, in worker
    "cov_gap": metric("CovGap")(val_prediction_sets, val_labels, alpha),
               ^^^^^^^^^^^^^^^^^^^^^^^^^^^^^^^^^^^^^^^^^^^^^^^^^^^^^^^^
TypeError: CovGap() missing 1 required positional argument: 'num_classes'

2025-01-26 00:30:21,577  | py-experimenter - INFO     | All configured executions finished.
2025-01-26 00:31:53,005  | py-experimenter - INFO     | Found 4 keyfields
2025-01-26 00:31:53,006  | py-experimenter - INFO     | Found 2 resultfields
2025-01-26 00:31:53,006  | py-experimenter - INFO     | Found 1 logtables
2025-01-26 00:31:53,006  | py-experimenter - INFO     | Found logtable cp_rank_dev__new_cross__results
2025-01-26 00:31:53,006  | py-experimenter - WARNING  | No custom section defined in config
2025-01-26 00:31:53,006  | py-experimenter - WARNING  | No codecarbon section defined in config
2025-01-26 00:31:53,007  | py-experimenter - INFO     | Initialized and connected to database
2025-01-26 00:31:53,067  | py-experimenter - INFO     | 1 rows successfully added to database. 0 rows were skipped.
2025-01-26 00:32:03,944  | py-experimenter - ERROR    | Traceback (most recent call last):
  File "/home/jonas/anaconda3/envs/plnet/lib/python3.11/site-packages/py_experimenter/experimenter.py", line 433, in _execute_experiment
    final_status = experiment_function(keyfield_values, result_processor, self.config.custom_configuration.custom_values)
                   ^^^^^^^^^^^^^^^^^^^^^^^^^^^^^^^^^^^^^^^^^^^^^^^^^^^^^^^^^^^^^^^^^^^^^^^^^^^^^^^^^^^^^^^^^^^^^^^^^^^^^^
  File "/home/jonas/Documents/Research/torch_plnet/experiments/simple_experiment_torchcp.py", line 294, in worker
    "vio_classes": metric("VioClasses")(
                   ^^^^^^^^^^^^^^^^^^^^^
TypeError: VioClasses() missing 1 required positional argument: 'num_classes'

2025-01-26 00:32:04,054  | py-experimenter - INFO     | All configured executions finished.
2025-01-26 00:32:36,541  | py-experimenter - INFO     | Found 4 keyfields
2025-01-26 00:32:36,541  | py-experimenter - INFO     | Found 2 resultfields
2025-01-26 00:32:36,542  | py-experimenter - INFO     | Found 1 logtables
2025-01-26 00:32:36,542  | py-experimenter - INFO     | Found logtable cp_rank_dev__new_cross__results
2025-01-26 00:32:36,542  | py-experimenter - WARNING  | No custom section defined in config
2025-01-26 00:32:36,542  | py-experimenter - WARNING  | No codecarbon section defined in config
2025-01-26 00:32:36,542  | py-experimenter - INFO     | Initialized and connected to database
2025-01-26 00:32:36,604  | py-experimenter - INFO     | 1 rows successfully added to database. 0 rows were skipped.
2025-01-26 00:32:44,547  | py-experimenter - ERROR    | Traceback (most recent call last):
  File "/home/jonas/anaconda3/envs/plnet/lib/python3.11/site-packages/py_experimenter/experimenter.py", line 433, in _execute_experiment
    final_status = experiment_function(keyfield_values, result_processor, self.config.custom_configuration.custom_values)
                   ^^^^^^^^^^^^^^^^^^^^^^^^^^^^^^^^^^^^^^^^^^^^^^^^^^^^^^^^^^^^^^^^^^^^^^^^^^^^^^^^^^^^^^^^^^^^^^^^^^^^^^
  File "/home/jonas/Documents/Research/torch_plnet/experiments/simple_experiment_torchcp.py", line 297, in worker
    "diff_violation": metric("DiffViolation")(
                      ^^^^^^^^^^^^^^^^^^^^^^^^
TypeError: DiffViolation() missing 1 required positional argument: 'alpha'

2025-01-26 00:32:44,651  | py-experimenter - INFO     | All configured executions finished.
2025-01-26 00:33:11,018  | py-experimenter - INFO     | Found 4 keyfields
2025-01-26 00:33:11,018  | py-experimenter - INFO     | Found 2 resultfields
2025-01-26 00:33:11,019  | py-experimenter - INFO     | Found 1 logtables
2025-01-26 00:33:11,019  | py-experimenter - INFO     | Found logtable cp_rank_dev__new_cross__results
2025-01-26 00:33:11,019  | py-experimenter - WARNING  | No custom section defined in config
2025-01-26 00:33:11,019  | py-experimenter - WARNING  | No codecarbon section defined in config
2025-01-26 00:33:11,020  | py-experimenter - INFO     | Initialized and connected to database
2025-01-26 00:33:11,081  | py-experimenter - INFO     | 1 rows successfully added to database. 0 rows were skipped.
2025-01-26 00:33:19,819  | py-experimenter - ERROR    | Traceback (most recent call last):
  File "/home/jonas/anaconda3/envs/plnet/lib/python3.11/site-packages/py_experimenter/experimenter.py", line 433, in _execute_experiment
    final_status = experiment_function(keyfield_values, result_processor, self.config.custom_configuration.custom_values)
                   ^^^^^^^^^^^^^^^^^^^^^^^^^^^^^^^^^^^^^^^^^^^^^^^^^^^^^^^^^^^^^^^^^^^^^^^^^^^^^^^^^^^^^^^^^^^^^^^^^^^^^^
  File "/home/jonas/Documents/Research/torch_plnet/experiments/simple_experiment_torchcp.py", line 301, in worker
    "wsc": metric("WSC")(val_features, val_prediction_sets, val_labels),
           ^^^^^^^^^^^^^^^^^^^^^^^^^^^^^^^^^^^^^^^^^^^^^^^^^^^^^^^^^^^^
  File "/home/jonas/anaconda3/envs/plnet/lib/python3.11/site-packages/torchcp/classification/utils/metrics.py", line 311, in WSC
    raise ValueError(
ValueError: Number of classes mismatch: prediction_sets has 6 classes but labels has 5 unique classes

2025-01-26 00:33:19,939  | py-experimenter - INFO     | All configured executions finished.
2025-01-26 00:34:38,849  | py-experimenter - INFO     | Found 4 keyfields
2025-01-26 00:34:38,849  | py-experimenter - INFO     | Found 2 resultfields
2025-01-26 00:34:38,850  | py-experimenter - INFO     | Found 1 logtables
2025-01-26 00:34:38,850  | py-experimenter - INFO     | Found logtable cp_rank_dev__new_cross__results
2025-01-26 00:34:38,850  | py-experimenter - WARNING  | No custom section defined in config
2025-01-26 00:34:38,850  | py-experimenter - WARNING  | No codecarbon section defined in config
2025-01-26 00:34:38,850  | py-experimenter - INFO     | Initialized and connected to database
2025-01-26 00:34:38,874  | py-experimenter - INFO     | 1 rows successfully added to database. 0 rows were skipped.
2025-01-26 00:34:50,167  | py-experimenter - INFO     | All configured executions finished.
2025-01-26 00:37:54,911  | py-experimenter - INFO     | Found 4 keyfields
2025-01-26 00:37:54,911  | py-experimenter - INFO     | Found 2 resultfields
2025-01-26 00:37:54,912  | py-experimenter - INFO     | Found 1 logtables
2025-01-26 00:37:54,912  | py-experimenter - INFO     | Found logtable cp_rank_dev__new_cross__results
2025-01-26 00:37:54,912  | py-experimenter - WARNING  | No custom section defined in config
2025-01-26 00:37:54,912  | py-experimenter - WARNING  | No codecarbon section defined in config
2025-01-26 00:37:54,912  | py-experimenter - INFO     | Initialized and connected to database
2025-01-26 00:37:54,973  | py-experimenter - INFO     | 1 rows successfully added to database. 0 rows were skipped.
2025-01-26 00:38:31,527  | py-experimenter - INFO     | All configured executions finished.
2025-01-26 11:32:13,872  | py-experimenter - INFO     | Found 4 keyfields
2025-01-26 11:32:13,873  | py-experimenter - INFO     | Found 2 resultfields
2025-01-26 11:32:13,873  | py-experimenter - INFO     | Found 1 logtables
2025-01-26 11:32:13,873  | py-experimenter - INFO     | Found logtable cp_rank_dev__new_cross__results
2025-01-26 11:32:13,874  | py-experimenter - WARNING  | No custom section defined in config
2025-01-26 11:32:13,874  | py-experimenter - WARNING  | No codecarbon section defined in config
2025-01-26 11:32:13,874  | py-experimenter - INFO     | Initialized and connected to database
2025-01-26 11:32:13,933  | py-experimenter - INFO     | 1 rows successfully added to database. 0 rows were skipped.
2025-01-26 11:32:22,394  | py-experimenter - ERROR    | Traceback (most recent call last):
  File "/home/jonas/anaconda3/envs/plnet/lib/python3.11/site-packages/py_experimenter/experimenter.py", line 433, in _execute_experiment
    final_status = experiment_function(keyfield_values, result_processor, self.config.custom_configuration.custom_values)
                   ^^^^^^^^^^^^^^^^^^^^^^^^^^^^^^^^^^^^^^^^^^^^^^^^^^^^^^^^^^^^^^^^^^^^^^^^^^^^^^^^^^^^^^^^^^^^^^^^^^^^^^
  File "/home/jonas/Documents/Research/torch_plnet/experiments/simple_experiment_torchcp.py", line 331, in worker
    f1 = f1_score(y_true, y_pred)
         ^^^^^^^^^^^^^^^^^^^^^^^^
  File "/home/jonas/anaconda3/envs/plnet/lib/python3.11/site-packages/sklearn/utils/_param_validation.py", line 213, in wrapper
    return func(*args, **kwargs)
           ^^^^^^^^^^^^^^^^^^^^^
  File "/home/jonas/anaconda3/envs/plnet/lib/python3.11/site-packages/sklearn/metrics/_classification.py", line 1293, in f1_score
    return fbeta_score(
           ^^^^^^^^^^^^
  File "/home/jonas/anaconda3/envs/plnet/lib/python3.11/site-packages/sklearn/utils/_param_validation.py", line 186, in wrapper
    return func(*args, **kwargs)
           ^^^^^^^^^^^^^^^^^^^^^
  File "/home/jonas/anaconda3/envs/plnet/lib/python3.11/site-packages/sklearn/metrics/_classification.py", line 1485, in fbeta_score
    _, _, f, _ = precision_recall_fscore_support(
                 ^^^^^^^^^^^^^^^^^^^^^^^^^^^^^^^^
  File "/home/jonas/anaconda3/envs/plnet/lib/python3.11/site-packages/sklearn/utils/_param_validation.py", line 186, in wrapper
    return func(*args, **kwargs)
           ^^^^^^^^^^^^^^^^^^^^^
  File "/home/jonas/anaconda3/envs/plnet/lib/python3.11/site-packages/sklearn/metrics/_classification.py", line 1789, in precision_recall_fscore_support
    labels = _check_set_wise_labels(y_true, y_pred, average, labels, pos_label)
             ^^^^^^^^^^^^^^^^^^^^^^^^^^^^^^^^^^^^^^^^^^^^^^^^^^^^^^^^^^^^^^^^^^
  File "/home/jonas/anaconda3/envs/plnet/lib/python3.11/site-packages/sklearn/metrics/_classification.py", line 1578, in _check_set_wise_labels
    raise ValueError(
ValueError: Target is multiclass but average='binary'. Please choose another average setting, one of [None, 'micro', 'macro', 'weighted'].

2025-01-26 11:32:22,497  | py-experimenter - INFO     | All configured executions finished.
2025-01-26 11:32:52,082  | py-experimenter - INFO     | Found 4 keyfields
2025-01-26 11:32:52,082  | py-experimenter - INFO     | Found 2 resultfields
2025-01-26 11:32:52,083  | py-experimenter - INFO     | Found 1 logtables
2025-01-26 11:32:52,083  | py-experimenter - INFO     | Found logtable cp_rank_dev__new_cross__results
2025-01-26 11:32:52,083  | py-experimenter - WARNING  | No custom section defined in config
2025-01-26 11:32:52,083  | py-experimenter - WARNING  | No codecarbon section defined in config
2025-01-26 11:32:52,084  | py-experimenter - INFO     | Initialized and connected to database
2025-01-26 11:32:52,142  | py-experimenter - INFO     | 1 rows successfully added to database. 0 rows were skipped.
2025-01-26 11:33:04,206  | py-experimenter - INFO     | All configured executions finished.
2025-01-26 12:00:26,590  | py-experimenter - INFO     | Found 4 keyfields
2025-01-26 12:00:26,590  | py-experimenter - INFO     | Found 2 resultfields
2025-01-26 12:00:26,591  | py-experimenter - INFO     | Found 1 logtables
2025-01-26 12:00:26,591  | py-experimenter - INFO     | Found logtable cp_rank_dev__new_cross__results
2025-01-26 12:00:26,591  | py-experimenter - WARNING  | No custom section defined in config
2025-01-26 12:00:26,591  | py-experimenter - WARNING  | No codecarbon section defined in config
2025-01-26 12:00:26,592  | py-experimenter - INFO     | Initialized and connected to database
2025-01-26 12:00:26,641  | py-experimenter - INFO     | 1 rows successfully added to database. 0 rows were skipped.
2025-01-26 12:00:33,849  | py-experimenter - ERROR    | Traceback (most recent call last):
  File "/home/jonas/anaconda3/envs/plnet/lib/python3.11/site-packages/py_experimenter/experimenter.py", line 433, in _execute_experiment
    final_status = experiment_function(keyfield_values, result_processor, self.config.custom_configuration.custom_values)
                   ^^^^^^^^^^^^^^^^^^^^^^^^^^^^^^^^^^^^^^^^^^^^^^^^^^^^^^^^^^^^^^^^^^^^^^^^^^^^^^^^^^^^^^^^^^^^^^^^^^^^^^
  File "/home/jonas/Documents/Research/torch_plnet/experiments/simple_experiment_torchcp.py", line 144, in worker
    X, y, _, _ = dataset.get_data(
                 ^^^^^^^^^^^^^^^^^
  File "/home/jonas/anaconda3/envs/plnet/lib/python3.11/site-packages/openml/datasets/dataset.py", line 803, in get_data
    data, categorical, attribute_names = self._load_data()
                                         ^^^^^^^^^^^^^^^^^
  File "/home/jonas/anaconda3/envs/plnet/lib/python3.11/site-packages/openml/datasets/dataset.py", line 594, in _load_data
    return self._cache_compressed_file_from_file(Path(file_to_load))
           ^^^^^^^^^^^^^^^^^^^^^^^^^^^^^^^^^^^^^^^^^^^^^^^^^^^^^^^^^
  File "/home/jonas/anaconda3/envs/plnet/lib/python3.11/site-packages/openml/datasets/dataset.py", line 539, in _cache_compressed_file_from_file
    attribute_names, categorical, data = self._parse_data_from_file(data_file)
                                         ^^^^^^^^^^^^^^^^^^^^^^^^^^^^^^^^^^^^^
  File "/home/jonas/anaconda3/envs/plnet/lib/python3.11/site-packages/openml/datasets/dataset.py", line 571, in _parse_data_from_file
    raise ValueError(f"Unknown file type for file '{data_file}'.")
ValueError: Unknown file type for file 'None'.

2025-01-26 12:00:33,938  | py-experimenter - INFO     | All configured executions finished.
2025-01-26 12:01:36,203  | py-experimenter - INFO     | Found 4 keyfields
2025-01-26 12:01:36,204  | py-experimenter - INFO     | Found 2 resultfields
2025-01-26 12:01:36,204  | py-experimenter - INFO     | Found 1 logtables
2025-01-26 12:01:36,204  | py-experimenter - INFO     | Found logtable cp_rank_dev__new_cross__results
2025-01-26 12:01:36,204  | py-experimenter - WARNING  | No custom section defined in config
2025-01-26 12:01:36,205  | py-experimenter - WARNING  | No codecarbon section defined in config
2025-01-26 12:01:36,205  | py-experimenter - INFO     | Initialized and connected to database
2025-01-26 12:01:36,228  | py-experimenter - INFO     | 1 rows successfully added to database. 0 rows were skipped.
2025-01-26 12:01:43,259  | py-experimenter - ERROR    | Traceback (most recent call last):
  File "/home/jonas/anaconda3/envs/plnet/lib/python3.11/site-packages/py_experimenter/experimenter.py", line 433, in _execute_experiment
    final_status = experiment_function(keyfield_values, result_processor, self.config.custom_configuration.custom_values)
                   ^^^^^^^^^^^^^^^^^^^^^^^^^^^^^^^^^^^^^^^^^^^^^^^^^^^^^^^^^^^^^^^^^^^^^^^^^^^^^^^^^^^^^^^^^^^^^^^^^^^^^^
  File "/home/jonas/Documents/Research/torch_plnet/experiments/simple_experiment_torchcp.py", line 144, in worker
    X, y, _, _ = dataset.get_data(
                 ^^^^^^^^^^^^^^^^^
  File "/home/jonas/anaconda3/envs/plnet/lib/python3.11/site-packages/openml/datasets/dataset.py", line 803, in get_data
    data, categorical, attribute_names = self._load_data()
                                         ^^^^^^^^^^^^^^^^^
  File "/home/jonas/anaconda3/envs/plnet/lib/python3.11/site-packages/openml/datasets/dataset.py", line 594, in _load_data
    return self._cache_compressed_file_from_file(Path(file_to_load))
           ^^^^^^^^^^^^^^^^^^^^^^^^^^^^^^^^^^^^^^^^^^^^^^^^^^^^^^^^^
  File "/home/jonas/anaconda3/envs/plnet/lib/python3.11/site-packages/openml/datasets/dataset.py", line 539, in _cache_compressed_file_from_file
    attribute_names, categorical, data = self._parse_data_from_file(data_file)
                                         ^^^^^^^^^^^^^^^^^^^^^^^^^^^^^^^^^^^^^
  File "/home/jonas/anaconda3/envs/plnet/lib/python3.11/site-packages/openml/datasets/dataset.py", line 571, in _parse_data_from_file
    raise ValueError(f"Unknown file type for file '{data_file}'.")
ValueError: Unknown file type for file 'None'.

2025-01-26 12:01:43,375  | py-experimenter - INFO     | All configured executions finished.
2025-01-26 12:02:01,190  | py-experimenter - INFO     | Found 4 keyfields
2025-01-26 12:02:01,191  | py-experimenter - INFO     | Found 2 resultfields
2025-01-26 12:02:01,192  | py-experimenter - INFO     | Found 1 logtables
2025-01-26 12:02:01,193  | py-experimenter - INFO     | Found logtable cp_rank_dev__new_cross__results
2025-01-26 12:02:01,193  | py-experimenter - WARNING  | No custom section defined in config
2025-01-26 12:02:01,193  | py-experimenter - WARNING  | No codecarbon section defined in config
2025-01-26 12:02:01,194  | py-experimenter - INFO     | Initialized and connected to database
2025-01-26 12:02:01,211  | py-experimenter - INFO     | 2 rows successfully added to database. 0 rows were skipped.
2025-01-26 12:04:22,537  | py-experimenter - INFO     | Found 4 keyfields
2025-01-26 12:04:22,537  | py-experimenter - INFO     | Found 2 resultfields
2025-01-26 12:04:22,537  | py-experimenter - INFO     | Found 1 logtables
2025-01-26 12:04:22,537  | py-experimenter - INFO     | Found logtable cp_rank_dev__new_cross__results
2025-01-26 12:04:22,537  | py-experimenter - WARNING  | No custom section defined in config
2025-01-26 12:04:22,537  | py-experimenter - WARNING  | No codecarbon section defined in config
2025-01-26 12:04:22,538  | py-experimenter - INFO     | Initialized and connected to database
2025-01-26 12:04:22,590  | py-experimenter - INFO     | 2 rows successfully added to database. 0 rows were skipped.
2025-01-26 12:04:32,104  | py-experimenter - ERROR    | Traceback (most recent call last):
  File "/home/jonas/anaconda3/envs/plnet/lib/python3.11/site-packages/py_experimenter/experimenter.py", line 433, in _execute_experiment
    final_status = experiment_function(keyfield_values, result_processor, self.config.custom_configuration.custom_values)
                   ^^^^^^^^^^^^^^^^^^^^^^^^^^^^^^^^^^^^^^^^^^^^^^^^^^^^^^^^^^^^^^^^^^^^^^^^^^^^^^^^^^^^^^^^^^^^^^^^^^^^^^
  File "/home/jonas/Documents/Research/torch_plnet/experiments/simple_experiment_torchcp.py", line 281, in worker
    val_predictions = torch.cat(predictions_list, dim=0)
                      ^^^^^^^^^^^^^^^^^^^^^^^^^^^^^^^^^^
RuntimeError: zero-dimensional tensor (at position 0) cannot be concatenated

2025-01-26 12:04:35,817  | py-experimenter - ERROR    | Traceback (most recent call last):
  File "/home/jonas/anaconda3/envs/plnet/lib/python3.11/site-packages/py_experimenter/experimenter.py", line 433, in _execute_experiment
    final_status = experiment_function(keyfield_values, result_processor, self.config.custom_configuration.custom_values)
                   ^^^^^^^^^^^^^^^^^^^^^^^^^^^^^^^^^^^^^^^^^^^^^^^^^^^^^^^^^^^^^^^^^^^^^^^^^^^^^^^^^^^^^^^^^^^^^^^^^^^^^^
  File "/home/jonas/Documents/Research/torch_plnet/experiments/simple_experiment_torchcp.py", line 281, in worker
    val_predictions = torch.cat(predictions_list, dim=0)
                      ^^^^^^^^^^^^^^^^^^^^^^^^^^^^^^^^^^
RuntimeError: zero-dimensional tensor (at position 0) cannot be concatenated

2025-01-26 12:04:35,873  | py-experimenter - INFO     | All configured executions finished.
2025-01-26 14:25:40,392  | py-experimenter - INFO     | Found 4 keyfields
2025-01-26 14:25:40,392  | py-experimenter - INFO     | Found 2 resultfields
2025-01-26 14:25:40,393  | py-experimenter - INFO     | Found 1 logtables
2025-01-26 14:25:40,393  | py-experimenter - INFO     | Found logtable cp_rank_dev__new_cross__results
2025-01-26 14:25:40,393  | py-experimenter - WARNING  | No custom section defined in config
2025-01-26 14:25:40,393  | py-experimenter - WARNING  | No codecarbon section defined in config
2025-01-26 14:25:40,394  | py-experimenter - INFO     | Initialized and connected to database
2025-01-26 14:25:40,455  | py-experimenter - INFO     | 2 rows successfully added to database. 0 rows were skipped.
2025-01-26 14:25:51,237  | py-experimenter - ERROR    | Traceback (most recent call last):
  File "/home/jonas/anaconda3/envs/plnet/lib/python3.11/site-packages/py_experimenter/experimenter.py", line 433, in _execute_experiment
    final_status = experiment_function(keyfield_values, result_processor, self.config.custom_configuration.custom_values)
                   ^^^^^^^^^^^^^^^^^^^^^^^^^^^^^^^^^^^^^^^^^^^^^^^^^^^^^^^^^^^^^^^^^^^^^^^^^^^^^^^^^^^^^^^^^^^^^^^^^^^^^^
  File "/home/jonas/Documents/Research/torch_plnet/experiments/simple_experiment_torchcp.py", line 282, in worker
    val_predictions = torch.cat(predictions_list, dim=0)
                      ^^^^^^^^^^^^^^^^^^^^^^^^^^^^^^^^^^
RuntimeError: zero-dimensional tensor (at position 0) cannot be concatenated

2025-01-26 14:25:52,881  | py-experimenter - ERROR    | Traceback (most recent call last):
  File "/home/jonas/anaconda3/envs/plnet/lib/python3.11/site-packages/py_experimenter/experimenter.py", line 433, in _execute_experiment
    final_status = experiment_function(keyfield_values, result_processor, self.config.custom_configuration.custom_values)
                   ^^^^^^^^^^^^^^^^^^^^^^^^^^^^^^^^^^^^^^^^^^^^^^^^^^^^^^^^^^^^^^^^^^^^^^^^^^^^^^^^^^^^^^^^^^^^^^^^^^^^^^
  File "/home/jonas/Documents/Research/torch_plnet/experiments/simple_experiment_torchcp.py", line 282, in worker
    val_predictions = torch.cat(predictions_list, dim=0)
                      ^^^^^^^^^^^^^^^^^^^^^^^^^^^^^^^^^^
RuntimeError: zero-dimensional tensor (at position 0) cannot be concatenated

2025-01-26 14:25:52,922  | py-experimenter - INFO     | All configured executions finished.
2025-01-26 14:27:01,765  | py-experimenter - INFO     | Found 4 keyfields
2025-01-26 14:27:01,765  | py-experimenter - INFO     | Found 2 resultfields
2025-01-26 14:27:01,765  | py-experimenter - INFO     | Found 1 logtables
2025-01-26 14:27:01,765  | py-experimenter - INFO     | Found logtable cp_rank_dev__new_cross__results
2025-01-26 14:27:01,765  | py-experimenter - WARNING  | No custom section defined in config
2025-01-26 14:27:01,765  | py-experimenter - WARNING  | No codecarbon section defined in config
2025-01-26 14:27:01,765  | py-experimenter - INFO     | Initialized and connected to database
2025-01-26 14:27:01,818  | py-experimenter - INFO     | 2 rows successfully added to database. 0 rows were skipped.
2025-01-26 14:27:11,210  | py-experimenter - ERROR    | Traceback (most recent call last):
  File "/home/jonas/anaconda3/envs/plnet/lib/python3.11/site-packages/py_experimenter/experimenter.py", line 433, in _execute_experiment
    final_status = experiment_function(keyfield_values, result_processor, self.config.custom_configuration.custom_values)
                   ^^^^^^^^^^^^^^^^^^^^^^^^^^^^^^^^^^^^^^^^^^^^^^^^^^^^^^^^^^^^^^^^^^^^^^^^^^^^^^^^^^^^^^^^^^^^^^^^^^^^^^
  File "/home/jonas/Documents/Research/torch_plnet/experiments/simple_experiment_torchcp.py", line 270, in worker
    # Accumulate predictions and labels
          ^^^^^
NameError: name 'label' is not defined

2025-01-26 14:27:14,445  | py-experimenter - ERROR    | Traceback (most recent call last):
  File "/home/jonas/anaconda3/envs/plnet/lib/python3.11/site-packages/py_experimenter/experimenter.py", line 433, in _execute_experiment
    final_status = experiment_function(keyfield_values, result_processor, self.config.custom_configuration.custom_values)
                   ^^^^^^^^^^^^^^^^^^^^^^^^^^^^^^^^^^^^^^^^^^^^^^^^^^^^^^^^^^^^^^^^^^^^^^^^^^^^^^^^^^^^^^^^^^^^^^^^^^^^^^
  File "/home/jonas/Documents/Research/torch_plnet/experiments/simple_experiment_torchcp.py", line 270, in worker
    # Accumulate predictions and labels
          ^^^^^
NameError: name 'label' is not defined

2025-01-26 14:27:14,493  | py-experimenter - INFO     | All configured executions finished.
2025-01-26 14:27:22,089  | py-experimenter - INFO     | Found 4 keyfields
2025-01-26 14:27:22,089  | py-experimenter - INFO     | Found 2 resultfields
2025-01-26 14:27:22,089  | py-experimenter - INFO     | Found 1 logtables
2025-01-26 14:27:22,089  | py-experimenter - INFO     | Found logtable cp_rank_dev__new_cross__results
2025-01-26 14:27:22,089  | py-experimenter - WARNING  | No custom section defined in config
2025-01-26 14:27:22,089  | py-experimenter - WARNING  | No codecarbon section defined in config
2025-01-26 14:27:22,089  | py-experimenter - INFO     | Initialized and connected to database
2025-01-26 14:27:22,142  | py-experimenter - INFO     | 2 rows successfully added to database. 0 rows were skipped.
2025-01-26 14:27:41,354  | py-experimenter - INFO     | All configured executions finished.
2025-01-26 18:33:07,715  | py-experimenter - INFO     | Found 4 keyfields
2025-01-26 18:33:07,716  | py-experimenter - INFO     | Found 2 resultfields
2025-01-26 18:33:07,716  | py-experimenter - INFO     | Found 1 logtables
2025-01-26 18:33:07,716  | py-experimenter - INFO     | Found logtable cp_rank_dev__new_cross__results
2025-01-26 18:33:07,716  | py-experimenter - WARNING  | No custom section defined in config
2025-01-26 18:33:07,716  | py-experimenter - WARNING  | No codecarbon section defined in config
2025-01-26 18:33:07,717  | py-experimenter - INFO     | Initialized and connected to database
2025-01-26 18:33:07,772  | py-experimenter - INFO     | 2 rows successfully added to database. 0 rows were skipped.
2025-01-26 18:33:58,083  | py-experimenter - ERROR    | Traceback (most recent call last):
  File "/home/jonas/anaconda3/envs/plnet/lib/python3.11/site-packages/py_experimenter/experimenter.py", line 433, in _execute_experiment
    final_status = experiment_function(keyfield_values, result_processor, self.config.custom_configuration.custom_values)
                   ^^^^^^^^^^^^^^^^^^^^^^^^^^^^^^^^^^^^^^^^^^^^^^^^^^^^^^^^^^^^^^^^^^^^^^^^^^^^^^^^^^^^^^^^^^^^^^^^^^^^^^
  File "/home/jonas/Documents/Research/torch_plnet/experiments/simple_experiment_torchcp.py", line 335, in worker
    evaluate_predictions(
    ^^^^^^^^^^^^^^^^^^^^
NameError: name 'evaluate_predictions' is not defined

2025-01-26 18:35:36,063  | py-experimenter - ERROR    | Traceback (most recent call last):
  File "/home/jonas/anaconda3/envs/plnet/lib/python3.11/site-packages/py_experimenter/experimenter.py", line 433, in _execute_experiment
    final_status = experiment_function(keyfield_values, result_processor, self.config.custom_configuration.custom_values)
                   ^^^^^^^^^^^^^^^^^^^^^^^^^^^^^^^^^^^^^^^^^^^^^^^^^^^^^^^^^^^^^^^^^^^^^^^^^^^^^^^^^^^^^^^^^^^^^^^^^^^^^^
  File "/home/jonas/Documents/Research/torch_plnet/experiments/simple_experiment_torchcp.py", line 335, in worker
    evaluate_predictions(
    ^^^^^^^^^^^^^^^^^^^^
NameError: name 'evaluate_predictions' is not defined

2025-01-26 18:35:36,386  | py-experimenter - ERROR    | Traceback (most recent call last):
  File "/home/jonas/anaconda3/envs/plnet/lib/python3.11/site-packages/py_experimenter/experimenter.py", line 433, in _execute_experiment
    final_status = experiment_function(keyfield_values, result_processor, self.config.custom_configuration.custom_values)
                   ^^^^^^^^^^^^^^^^^^^^^^^^^^^^^^^^^^^^^^^^^^^^^^^^^^^^^^^^^^^^^^^^^^^^^^^^^^^^^^^^^^^^^^^^^^^^^^^^^^^^^^
  File "/home/jonas/Documents/Research/torch_plnet/experiments/simple_experiment_torchcp.py", line 335, in worker
    evaluate_predictions(
    ^^^^^^^^^^^^^^^^^^^^
NameError: name 'evaluate_predictions' is not defined

2025-01-26 18:35:36,414  | py-experimenter - ERROR    | Traceback (most recent call last):
  File "/home/jonas/anaconda3/envs/plnet/lib/python3.11/site-packages/py_experimenter/experimenter.py", line 433, in _execute_experiment
    final_status = experiment_function(keyfield_values, result_processor, self.config.custom_configuration.custom_values)
                   ^^^^^^^^^^^^^^^^^^^^^^^^^^^^^^^^^^^^^^^^^^^^^^^^^^^^^^^^^^^^^^^^^^^^^^^^^^^^^^^^^^^^^^^^^^^^^^^^^^^^^^
  File "/home/jonas/Documents/Research/torch_plnet/experiments/simple_experiment_torchcp.py", line 335, in worker
    evaluate_predictions(
    ^^^^^^^^^^^^^^^^^^^^
NameError: name 'evaluate_predictions' is not defined

2025-01-26 18:35:36,601  | py-experimenter - ERROR    | Traceback (most recent call last):
  File "/home/jonas/anaconda3/envs/plnet/lib/python3.11/site-packages/py_experimenter/experimenter.py", line 433, in _execute_experiment
    final_status = experiment_function(keyfield_values, result_processor, self.config.custom_configuration.custom_values)
                   ^^^^^^^^^^^^^^^^^^^^^^^^^^^^^^^^^^^^^^^^^^^^^^^^^^^^^^^^^^^^^^^^^^^^^^^^^^^^^^^^^^^^^^^^^^^^^^^^^^^^^^
  File "/home/jonas/Documents/Research/torch_plnet/experiments/simple_experiment_torchcp.py", line 335, in worker
    evaluate_predictions(
    ^^^^^^^^^^^^^^^^^^^^
NameError: name 'evaluate_predictions' is not defined

2025-01-26 18:35:36,669  | py-experimenter - ERROR    | Traceback (most recent call last):
  File "/home/jonas/anaconda3/envs/plnet/lib/python3.11/site-packages/py_experimenter/experimenter.py", line 433, in _execute_experiment
    final_status = experiment_function(keyfield_values, result_processor, self.config.custom_configuration.custom_values)
                   ^^^^^^^^^^^^^^^^^^^^^^^^^^^^^^^^^^^^^^^^^^^^^^^^^^^^^^^^^^^^^^^^^^^^^^^^^^^^^^^^^^^^^^^^^^^^^^^^^^^^^^
  File "/home/jonas/Documents/Research/torch_plnet/experiments/simple_experiment_torchcp.py", line 335, in worker
    evaluate_predictions(
    ^^^^^^^^^^^^^^^^^^^^
NameError: name 'evaluate_predictions' is not defined

2025-01-26 18:35:36,698  | py-experimenter - INFO     | All configured executions finished.
2025-01-26 18:36:37,174  | py-experimenter - INFO     | Found 4 keyfields
2025-01-26 18:36:37,174  | py-experimenter - INFO     | Found 2 resultfields
2025-01-26 18:36:37,175  | py-experimenter - INFO     | Found 1 logtables
2025-01-26 18:36:37,175  | py-experimenter - INFO     | Found logtable cp_rank_dev__new_cross__results
2025-01-26 18:36:37,175  | py-experimenter - WARNING  | No custom section defined in config
2025-01-26 18:36:37,175  | py-experimenter - WARNING  | No codecarbon section defined in config
2025-01-26 18:36:37,175  | py-experimenter - INFO     | Initialized and connected to database
2025-01-26 18:36:37,234  | py-experimenter - INFO     | 2 rows successfully added to database. 0 rows were skipped.
2025-01-26 18:36:46,522  | py-experimenter - ERROR    | Traceback (most recent call last):
  File "/home/jonas/anaconda3/envs/plnet/lib/python3.11/site-packages/py_experimenter/experimenter.py", line 433, in _execute_experiment
    final_status = experiment_function(keyfield_values, result_processor, self.config.custom_configuration.custom_values)
                   ^^^^^^^^^^^^^^^^^^^^^^^^^^^^^^^^^^^^^^^^^^^^^^^^^^^^^^^^^^^^^^^^^^^^^^^^^^^^^^^^^^^^^^^^^^^^^^^^^^^^^^
  File "/home/jonas/Documents/Research/torch_plnet/experiments/simple_experiment_torchcp.py", line 304, in worker
    evaluate(
  File "/home/jonas/Documents/Research/torch_plnet/experiments/simple_experiment_torchcp.py", line 182, in evaluate
    result_processor.process_logs({"results": metrics})
  File "/home/jonas/anaconda3/envs/plnet/lib/python3.11/site-packages/py_experimenter/result_processor.py", line 78, in process_logs
    if not self._valid_logtable_logs(logs):
           ^^^^^^^^^^^^^^^^^^^^^^^^^^^^^^^
  File "/home/jonas/anaconda3/envs/plnet/lib/python3.11/site-packages/py_experimenter/result_processor.py", line 98, in _valid_logtable_logs
    for column, _ in logtable_entries.items():
                     ^^^^^^^^^^^^^^^^^^^^^^
AttributeError: 'NoneType' object has no attribute 'items'

2025-01-26 18:36:48,791  | py-experimenter - ERROR    | Traceback (most recent call last):
  File "/home/jonas/anaconda3/envs/plnet/lib/python3.11/site-packages/py_experimenter/experimenter.py", line 433, in _execute_experiment
    final_status = experiment_function(keyfield_values, result_processor, self.config.custom_configuration.custom_values)
                   ^^^^^^^^^^^^^^^^^^^^^^^^^^^^^^^^^^^^^^^^^^^^^^^^^^^^^^^^^^^^^^^^^^^^^^^^^^^^^^^^^^^^^^^^^^^^^^^^^^^^^^
  File "/home/jonas/Documents/Research/torch_plnet/experiments/simple_experiment_torchcp.py", line 304, in worker
    evaluate(
  File "/home/jonas/Documents/Research/torch_plnet/experiments/simple_experiment_torchcp.py", line 182, in evaluate
    result_processor.process_logs({"results": metrics})
  File "/home/jonas/anaconda3/envs/plnet/lib/python3.11/site-packages/py_experimenter/result_processor.py", line 78, in process_logs
    if not self._valid_logtable_logs(logs):
           ^^^^^^^^^^^^^^^^^^^^^^^^^^^^^^^
  File "/home/jonas/anaconda3/envs/plnet/lib/python3.11/site-packages/py_experimenter/result_processor.py", line 98, in _valid_logtable_logs
    for column, _ in logtable_entries.items():
                     ^^^^^^^^^^^^^^^^^^^^^^
AttributeError: 'NoneType' object has no attribute 'items'

2025-01-26 18:36:48,851  | py-experimenter - INFO     | All configured executions finished.
2025-01-26 18:46:44,161  | py-experimenter - INFO     | Found 4 keyfields
2025-01-26 18:46:44,161  | py-experimenter - INFO     | Found 2 resultfields
2025-01-26 18:46:44,161  | py-experimenter - INFO     | Found 1 logtables
2025-01-26 18:46:44,161  | py-experimenter - INFO     | Found logtable cp_rank_dev__new_cross__results
2025-01-26 18:46:44,161  | py-experimenter - WARNING  | No custom section defined in config
2025-01-26 18:46:44,161  | py-experimenter - WARNING  | No codecarbon section defined in config
2025-01-26 18:46:44,161  | py-experimenter - INFO     | Initialized and connected to database
2025-01-26 18:46:44,218  | py-experimenter - INFO     | 2 rows successfully added to database. 0 rows were skipped.
2025-01-26 18:47:08,804  | py-experimenter - ERROR    | Traceback (most recent call last):
  File "/home/jonas/anaconda3/envs/plnet/lib/python3.11/site-packages/py_experimenter/experimenter.py", line 433, in _execute_experiment
    final_status = experiment_function(keyfield_values, result_processor, self.config.custom_configuration.custom_values)
                   ^^^^^^^^^^^^^^^^^^^^^^^^^^^^^^^^^^^^^^^^^^^^^^^^^^^^^^^^^^^^^^^^^^^^^^^^^^^^^^^^^^^^^^^^^^^^^^^^^^^^^^
  File "/home/jonas/Documents/Research/torch_plnet/experiments/simple_experiment_torchcp.py", line 305, in worker
    evaluate(
  File "/home/jonas/Documents/Research/torch_plnet/experiments/simple_experiment_torchcp.py", line 183, in evaluate
    result_processor.process_logs({"results": metrics})
  File "/home/jonas/anaconda3/envs/plnet/lib/python3.11/site-packages/py_experimenter/result_processor.py", line 78, in process_logs
    if not self._valid_logtable_logs(logs):
           ^^^^^^^^^^^^^^^^^^^^^^^^^^^^^^^
  File "/home/jonas/anaconda3/envs/plnet/lib/python3.11/site-packages/py_experimenter/result_processor.py", line 98, in _valid_logtable_logs
    for column, _ in logtable_entries.items():
                     ^^^^^^^^^^^^^^^^^^^^^^
AttributeError: 'NoneType' object has no attribute 'items'

2025-01-26 18:48:05,361  | py-experimenter - ERROR    | Traceback (most recent call last):
  File "/home/jonas/anaconda3/envs/plnet/lib/python3.11/site-packages/py_experimenter/experimenter.py", line 433, in _execute_experiment
    final_status = experiment_function(keyfield_values, result_processor, self.config.custom_configuration.custom_values)
                   ^^^^^^^^^^^^^^^^^^^^^^^^^^^^^^^^^^^^^^^^^^^^^^^^^^^^^^^^^^^^^^^^^^^^^^^^^^^^^^^^^^^^^^^^^^^^^^^^^^^^^^
  File "/home/jonas/Documents/Research/torch_plnet/experiments/simple_experiment_torchcp.py", line 305, in worker
    evaluate(
  File "/home/jonas/Documents/Research/torch_plnet/experiments/simple_experiment_torchcp.py", line 183, in evaluate
    result_processor.process_logs({"results": metrics})
  File "/home/jonas/anaconda3/envs/plnet/lib/python3.11/site-packages/py_experimenter/result_processor.py", line 78, in process_logs
    if not self._valid_logtable_logs(logs):
           ^^^^^^^^^^^^^^^^^^^^^^^^^^^^^^^
  File "/home/jonas/anaconda3/envs/plnet/lib/python3.11/site-packages/py_experimenter/result_processor.py", line 98, in _valid_logtable_logs
    for column, _ in logtable_entries.items():
                     ^^^^^^^^^^^^^^^^^^^^^^
AttributeError: 'NoneType' object has no attribute 'items'

2025-01-26 18:48:05,554  | py-experimenter - ERROR    | Traceback (most recent call last):
  File "/home/jonas/anaconda3/envs/plnet/lib/python3.11/site-packages/py_experimenter/experimenter.py", line 433, in _execute_experiment
    final_status = experiment_function(keyfield_values, result_processor, self.config.custom_configuration.custom_values)
                   ^^^^^^^^^^^^^^^^^^^^^^^^^^^^^^^^^^^^^^^^^^^^^^^^^^^^^^^^^^^^^^^^^^^^^^^^^^^^^^^^^^^^^^^^^^^^^^^^^^^^^^
  File "/home/jonas/Documents/Research/torch_plnet/experiments/simple_experiment_torchcp.py", line 305, in worker
    evaluate(
  File "/home/jonas/Documents/Research/torch_plnet/experiments/simple_experiment_torchcp.py", line 183, in evaluate
    result_processor.process_logs({"results": metrics})
  File "/home/jonas/anaconda3/envs/plnet/lib/python3.11/site-packages/py_experimenter/result_processor.py", line 78, in process_logs
    if not self._valid_logtable_logs(logs):
           ^^^^^^^^^^^^^^^^^^^^^^^^^^^^^^^
  File "/home/jonas/anaconda3/envs/plnet/lib/python3.11/site-packages/py_experimenter/result_processor.py", line 98, in _valid_logtable_logs
    for column, _ in logtable_entries.items():
                     ^^^^^^^^^^^^^^^^^^^^^^
AttributeError: 'NoneType' object has no attribute 'items'

2025-01-26 18:48:05,639  | py-experimenter - ERROR    | Traceback (most recent call last):
  File "/home/jonas/anaconda3/envs/plnet/lib/python3.11/site-packages/py_experimenter/experimenter.py", line 433, in _execute_experiment
    final_status = experiment_function(keyfield_values, result_processor, self.config.custom_configuration.custom_values)
                   ^^^^^^^^^^^^^^^^^^^^^^^^^^^^^^^^^^^^^^^^^^^^^^^^^^^^^^^^^^^^^^^^^^^^^^^^^^^^^^^^^^^^^^^^^^^^^^^^^^^^^^
  File "/home/jonas/Documents/Research/torch_plnet/experiments/simple_experiment_torchcp.py", line 305, in worker
    evaluate(
  File "/home/jonas/Documents/Research/torch_plnet/experiments/simple_experiment_torchcp.py", line 183, in evaluate
    result_processor.process_logs({"results": metrics})
  File "/home/jonas/anaconda3/envs/plnet/lib/python3.11/site-packages/py_experimenter/result_processor.py", line 78, in process_logs
    if not self._valid_logtable_logs(logs):
           ^^^^^^^^^^^^^^^^^^^^^^^^^^^^^^^
  File "/home/jonas/anaconda3/envs/plnet/lib/python3.11/site-packages/py_experimenter/result_processor.py", line 98, in _valid_logtable_logs
    for column, _ in logtable_entries.items():
                     ^^^^^^^^^^^^^^^^^^^^^^
AttributeError: 'NoneType' object has no attribute 'items'

2025-01-26 18:48:05,679  | py-experimenter - INFO     | All configured executions finished.
2025-01-26 19:01:20,007  | py-experimenter - INFO     | Found 4 keyfields
2025-01-26 19:01:20,007  | py-experimenter - INFO     | Found 2 resultfields
2025-01-26 19:01:20,008  | py-experimenter - INFO     | Found 1 logtables
2025-01-26 19:01:20,008  | py-experimenter - INFO     | Found logtable cp_rank_dev__new_cross__results
2025-01-26 19:01:20,008  | py-experimenter - WARNING  | No custom section defined in config
2025-01-26 19:01:20,008  | py-experimenter - WARNING  | No codecarbon section defined in config
2025-01-26 19:01:20,008  | py-experimenter - INFO     | Initialized and connected to database
2025-01-26 19:01:20,061  | py-experimenter - INFO     | 2 rows successfully added to database. 0 rows were skipped.
2025-01-26 19:01:38,923  | py-experimenter - ERROR    | Traceback (most recent call last):
  File "/home/jonas/anaconda3/envs/plnet/lib/python3.11/site-packages/py_experimenter/experimenter.py", line 433, in _execute_experiment
    final_status = experiment_function(keyfield_values, result_processor, self.config.custom_configuration.custom_values)
                   ^^^^^^^^^^^^^^^^^^^^^^^^^^^^^^^^^^^^^^^^^^^^^^^^^^^^^^^^^^^^^^^^^^^^^^^^^^^^^^^^^^^^^^^^^^^^^^^^^^^^^^
  File "/home/jonas/Documents/Research/torch_plnet/experiments/simple_experiment_torchcp.py", line 305, in worker
    evaluate(
  File "/home/jonas/Documents/Research/torch_plnet/experiments/simple_experiment_torchcp.py", line 183, in evaluate
    result_processor.process_logs({"results": metrics})
  File "/home/jonas/anaconda3/envs/plnet/lib/python3.11/site-packages/py_experimenter/result_processor.py", line 78, in process_logs
    if not self._valid_logtable_logs(logs):
           ^^^^^^^^^^^^^^^^^^^^^^^^^^^^^^^
  File "/home/jonas/anaconda3/envs/plnet/lib/python3.11/site-packages/py_experimenter/result_processor.py", line 98, in _valid_logtable_logs
    for column, _ in logtable_entries.items():
                     ^^^^^^^^^^^^^^^^^^^^^^
AttributeError: 'NoneType' object has no attribute 'items'

2025-01-26 19:02:07,733  | py-experimenter - ERROR    | Traceback (most recent call last):
  File "/home/jonas/anaconda3/envs/plnet/lib/python3.11/site-packages/py_experimenter/experimenter.py", line 433, in _execute_experiment
    final_status = experiment_function(keyfield_values, result_processor, self.config.custom_configuration.custom_values)
                   ^^^^^^^^^^^^^^^^^^^^^^^^^^^^^^^^^^^^^^^^^^^^^^^^^^^^^^^^^^^^^^^^^^^^^^^^^^^^^^^^^^^^^^^^^^^^^^^^^^^^^^
  File "/home/jonas/Documents/Research/torch_plnet/experiments/simple_experiment_torchcp.py", line 305, in worker
    evaluate(
  File "/home/jonas/Documents/Research/torch_plnet/experiments/simple_experiment_torchcp.py", line 183, in evaluate
    result_processor.process_logs({"results": metrics})
  File "/home/jonas/anaconda3/envs/plnet/lib/python3.11/site-packages/py_experimenter/result_processor.py", line 78, in process_logs
    if not self._valid_logtable_logs(logs):
           ^^^^^^^^^^^^^^^^^^^^^^^^^^^^^^^
  File "/home/jonas/anaconda3/envs/plnet/lib/python3.11/site-packages/py_experimenter/result_processor.py", line 98, in _valid_logtable_logs
    for column, _ in logtable_entries.items():
                     ^^^^^^^^^^^^^^^^^^^^^^
AttributeError: 'NoneType' object has no attribute 'items'

2025-01-26 19:02:07,762  | py-experimenter - ERROR    | Traceback (most recent call last):
  File "/home/jonas/anaconda3/envs/plnet/lib/python3.11/site-packages/py_experimenter/experimenter.py", line 433, in _execute_experiment
    final_status = experiment_function(keyfield_values, result_processor, self.config.custom_configuration.custom_values)
                   ^^^^^^^^^^^^^^^^^^^^^^^^^^^^^^^^^^^^^^^^^^^^^^^^^^^^^^^^^^^^^^^^^^^^^^^^^^^^^^^^^^^^^^^^^^^^^^^^^^^^^^
  File "/home/jonas/Documents/Research/torch_plnet/experiments/simple_experiment_torchcp.py", line 305, in worker
    evaluate(
  File "/home/jonas/Documents/Research/torch_plnet/experiments/simple_experiment_torchcp.py", line 183, in evaluate
    result_processor.process_logs({"results": metrics})
  File "/home/jonas/anaconda3/envs/plnet/lib/python3.11/site-packages/py_experimenter/result_processor.py", line 78, in process_logs
    if not self._valid_logtable_logs(logs):
           ^^^^^^^^^^^^^^^^^^^^^^^^^^^^^^^
  File "/home/jonas/anaconda3/envs/plnet/lib/python3.11/site-packages/py_experimenter/result_processor.py", line 98, in _valid_logtable_logs
    for column, _ in logtable_entries.items():
                     ^^^^^^^^^^^^^^^^^^^^^^
AttributeError: 'NoneType' object has no attribute 'items'

2025-01-26 19:02:07,790  | py-experimenter - INFO     | All configured executions finished.
2025-01-26 19:18:13,889  | py-experimenter - INFO     | Found 4 keyfields
2025-01-26 19:18:13,889  | py-experimenter - INFO     | Found 2 resultfields
2025-01-26 19:18:13,889  | py-experimenter - INFO     | Found 1 logtables
2025-01-26 19:18:13,889  | py-experimenter - INFO     | Found logtable cp_rank_dev__new_cross__results
2025-01-26 19:18:13,889  | py-experimenter - WARNING  | No custom section defined in config
2025-01-26 19:18:13,889  | py-experimenter - WARNING  | No codecarbon section defined in config
2025-01-26 19:18:13,889  | py-experimenter - INFO     | Initialized and connected to database
2025-01-26 19:18:13,944  | py-experimenter - INFO     | 2 rows successfully added to database. 0 rows were skipped.
2025-01-26 19:18:26,541  | py-experimenter - ERROR    | Traceback (most recent call last):
  File "/home/jonas/anaconda3/envs/plnet/lib/python3.11/site-packages/py_experimenter/database_connector.py", line 57, in execute
    cursor.execute(sql_statement, values)
sqlite3.ProgrammingError: Error binding parameter 5: type 'tuple' is not supported

During handling of the above exception, another exception occurred:

Traceback (most recent call last):
  File "/home/jonas/anaconda3/envs/plnet/lib/python3.11/site-packages/py_experimenter/experimenter.py", line 433, in _execute_experiment
    final_status = experiment_function(keyfield_values, result_processor, self.config.custom_configuration.custom_values)
                   ^^^^^^^^^^^^^^^^^^^^^^^^^^^^^^^^^^^^^^^^^^^^^^^^^^^^^^^^^^^^^^^^^^^^^^^^^^^^^^^^^^^^^^^^^^^^^^^^^^^^^^
  File "/home/jonas/Documents/Research/torch_plnet/experiments/simple_experiment_torchcp.py", line 305, in worker
    evaluate(
  File "/home/jonas/Documents/Research/torch_plnet/experiments/simple_experiment_torchcp.py", line 183, in evaluate
    result_processor.process_logs({"results": metrics})
  File "/home/jonas/anaconda3/envs/plnet/lib/python3.11/site-packages/py_experimenter/result_processor.py", line 89, in process_logs
    self.db_connector.execute_queries(queries)
  File "/home/jonas/anaconda3/envs/plnet/lib/python3.11/site-packages/py_experimenter/database_connector.py", line 377, in execute_queries
    self.execute(cursor, query[0], tuple(query[1]))
  File "/home/jonas/anaconda3/envs/plnet/lib/python3.11/site-packages/py_experimenter/database_connector.py", line 59, in execute
    raise DatabaseConnectionError(f"error \n{e}\n raised when executing sql statement.")
py_experimenter.exceptions.DatabaseConnectionError: error 
Error binding parameter 5: type 'tuple' is not supported
 raised when executing sql statement.

2025-01-26 19:18:33,653  | py-experimenter - ERROR    | Traceback (most recent call last):
  File "/home/jonas/anaconda3/envs/plnet/lib/python3.11/site-packages/py_experimenter/database_connector.py", line 57, in execute
    cursor.execute(sql_statement, values)
sqlite3.ProgrammingError: Error binding parameter 5: type 'tuple' is not supported

During handling of the above exception, another exception occurred:

Traceback (most recent call last):
  File "/home/jonas/anaconda3/envs/plnet/lib/python3.11/site-packages/py_experimenter/experimenter.py", line 433, in _execute_experiment
    final_status = experiment_function(keyfield_values, result_processor, self.config.custom_configuration.custom_values)
                   ^^^^^^^^^^^^^^^^^^^^^^^^^^^^^^^^^^^^^^^^^^^^^^^^^^^^^^^^^^^^^^^^^^^^^^^^^^^^^^^^^^^^^^^^^^^^^^^^^^^^^^
  File "/home/jonas/Documents/Research/torch_plnet/experiments/simple_experiment_torchcp.py", line 305, in worker
    evaluate(
  File "/home/jonas/Documents/Research/torch_plnet/experiments/simple_experiment_torchcp.py", line 183, in evaluate
    result_processor.process_logs({"results": metrics})
  File "/home/jonas/anaconda3/envs/plnet/lib/python3.11/site-packages/py_experimenter/result_processor.py", line 89, in process_logs
    self.db_connector.execute_queries(queries)
  File "/home/jonas/anaconda3/envs/plnet/lib/python3.11/site-packages/py_experimenter/database_connector.py", line 377, in execute_queries
    self.execute(cursor, query[0], tuple(query[1]))
  File "/home/jonas/anaconda3/envs/plnet/lib/python3.11/site-packages/py_experimenter/database_connector.py", line 59, in execute
    raise DatabaseConnectionError(f"error \n{e}\n raised when executing sql statement.")
py_experimenter.exceptions.DatabaseConnectionError: error 
Error binding parameter 5: type 'tuple' is not supported
 raised when executing sql statement.

2025-01-26 19:18:33,712  | py-experimenter - INFO     | All configured executions finished.
2025-01-26 19:20:09,185  | py-experimenter - INFO     | Found 4 keyfields
2025-01-26 19:20:09,185  | py-experimenter - INFO     | Found 2 resultfields
2025-01-26 19:20:09,185  | py-experimenter - INFO     | Found 1 logtables
2025-01-26 19:20:09,185  | py-experimenter - INFO     | Found logtable cp_rank_dev__new_cross__results
2025-01-26 19:20:09,186  | py-experimenter - WARNING  | No custom section defined in config
2025-01-26 19:20:09,186  | py-experimenter - WARNING  | No codecarbon section defined in config
2025-01-26 19:20:09,186  | py-experimenter - INFO     | Initialized and connected to database
2025-01-26 19:20:09,237  | py-experimenter - INFO     | 2 rows successfully added to database. 0 rows were skipped.
2025-01-26 19:20:39,060  | py-experimenter - INFO     | Found 4 keyfields
2025-01-26 19:20:39,061  | py-experimenter - INFO     | Found 2 resultfields
2025-01-26 19:20:39,061  | py-experimenter - INFO     | Found 1 logtables
2025-01-26 19:20:39,061  | py-experimenter - INFO     | Found logtable cp_rank_dev__new_cross__results
2025-01-26 19:20:39,061  | py-experimenter - WARNING  | No custom section defined in config
2025-01-26 19:20:39,061  | py-experimenter - WARNING  | No codecarbon section defined in config
2025-01-26 19:20:39,061  | py-experimenter - INFO     | Initialized and connected to database
2025-01-26 19:20:39,114  | py-experimenter - INFO     | 2 rows successfully added to database. 0 rows were skipped.
2025-01-26 19:21:01,298  | py-experimenter - INFO     | All configured executions finished.
2025-01-26 19:28:31,083  | py-experimenter - INFO     | Found 4 keyfields
2025-01-26 19:28:31,084  | py-experimenter - INFO     | Found 2 resultfields
2025-01-26 19:28:31,084  | py-experimenter - INFO     | Found 1 logtables
2025-01-26 19:28:31,084  | py-experimenter - INFO     | Found logtable cp_rank_dev__new_cross__results
2025-01-26 19:28:31,084  | py-experimenter - WARNING  | No custom section defined in config
2025-01-26 19:28:31,084  | py-experimenter - WARNING  | No codecarbon section defined in config
2025-01-26 19:28:31,084  | py-experimenter - INFO     | Initialized and connected to database
2025-01-26 19:28:31,085  | py-experimenter - INFO     | No rows to add. All the 2 experiments already exist.
2025-01-26 19:28:31,378  | py-experimenter - INFO     | All configured executions finished.
2025-01-26 19:28:44,151  | py-experimenter - INFO     | Found 4 keyfields
2025-01-26 19:28:44,151  | py-experimenter - INFO     | Found 2 resultfields
2025-01-26 19:28:44,151  | py-experimenter - INFO     | Found 1 logtables
2025-01-26 19:28:44,151  | py-experimenter - INFO     | Found logtable cp_rank_dev__new_cross__results
2025-01-26 19:28:44,152  | py-experimenter - WARNING  | No custom section defined in config
2025-01-26 19:28:44,152  | py-experimenter - WARNING  | No codecarbon section defined in config
2025-01-26 19:28:44,152  | py-experimenter - INFO     | Initialized and connected to database
2025-01-26 19:28:44,204  | py-experimenter - INFO     | 2 rows successfully added to database. 0 rows were skipped.
2025-01-26 19:29:10,489  | py-experimenter - INFO     | All configured executions finished.
2025-01-26 20:31:52,842  | py-experimenter - INFO     | Found 4 keyfields
2025-01-26 20:31:52,842  | py-experimenter - INFO     | Found 2 resultfields
2025-01-26 20:31:52,842  | py-experimenter - INFO     | Found 1 logtables
2025-01-26 20:31:52,842  | py-experimenter - INFO     | Found logtable cp_rank_dev__new_cross__results
2025-01-26 20:31:52,842  | py-experimenter - WARNING  | No custom section defined in config
2025-01-26 20:31:52,842  | py-experimenter - WARNING  | No codecarbon section defined in config
2025-01-26 20:31:52,843  | py-experimenter - INFO     | Initialized and connected to database
2025-01-26 20:31:52,886  | py-experimenter - INFO     | 2 rows successfully added to database. 0 rows were skipped.
2025-01-26 20:33:56,670  | py-experimenter - INFO     | All configured executions finished.
2025-01-26 20:38:51,726  | py-experimenter - INFO     | Found 4 keyfields
2025-01-26 20:38:51,727  | py-experimenter - INFO     | Found 2 resultfields
2025-01-26 20:38:51,727  | py-experimenter - INFO     | Found 1 logtables
2025-01-26 20:38:51,727  | py-experimenter - INFO     | Found logtable cp_rank_dev__new_cross__results
2025-01-26 20:38:51,727  | py-experimenter - WARNING  | No custom section defined in config
2025-01-26 20:38:51,727  | py-experimenter - WARNING  | No codecarbon section defined in config
2025-01-26 20:38:51,727  | py-experimenter - INFO     | Initialized and connected to database
2025-01-26 20:38:51,748  | py-experimenter - INFO     | 2 rows successfully added to database. 2 rows were skipped.
2025-01-26 20:38:52,059  | py-experimenter - ERROR    | Traceback (most recent call last):
  File "/home/jonas/anaconda3/envs/plnet/lib/python3.11/site-packages/py_experimenter/experimenter.py", line 433, in _execute_experiment
    final_status = experiment_function(keyfield_values, result_processor, self.config.custom_configuration.custom_values)
                   ^^^^^^^^^^^^^^^^^^^^^^^^^^^^^^^^^^^^^^^^^^^^^^^^^^^^^^^^^^^^^^^^^^^^^^^^^^^^^^^^^^^^^^^^^^^^^^^^^^^^^^
  File "/home/jonas/Documents/Research/torch_plnet/experiments/simple_experiment_torchcp.py", line 366, in worker
    model = LabelRankingModel(
            ^^^^^^^^^^^^^^^^^^
TypeError: LabelRankingModel.__init__() got an unexpected keyword argument 'hidden_dim'

2025-01-26 20:38:52,107  | py-experimenter - ERROR    | Traceback (most recent call last):
  File "/home/jonas/anaconda3/envs/plnet/lib/python3.11/site-packages/py_experimenter/experimenter.py", line 433, in _execute_experiment
    final_status = experiment_function(keyfield_values, result_processor, self.config.custom_configuration.custom_values)
                   ^^^^^^^^^^^^^^^^^^^^^^^^^^^^^^^^^^^^^^^^^^^^^^^^^^^^^^^^^^^^^^^^^^^^^^^^^^^^^^^^^^^^^^^^^^^^^^^^^^^^^^
  File "/home/jonas/Documents/Research/torch_plnet/experiments/simple_experiment_torchcp.py", line 366, in worker
    model = LabelRankingModel(
            ^^^^^^^^^^^^^^^^^^
TypeError: LabelRankingModel.__init__() got an unexpected keyword argument 'hidden_dim'

2025-01-26 20:38:52,186  | py-experimenter - INFO     | All configured executions finished.
2025-01-26 20:39:24,595  | py-experimenter - INFO     | Found 4 keyfields
2025-01-26 20:39:24,595  | py-experimenter - INFO     | Found 2 resultfields
2025-01-26 20:39:24,595  | py-experimenter - INFO     | Found 1 logtables
2025-01-26 20:39:24,595  | py-experimenter - INFO     | Found logtable cp_rank_dev__new_cross__results
2025-01-26 20:39:24,595  | py-experimenter - WARNING  | No custom section defined in config
2025-01-26 20:39:24,595  | py-experimenter - WARNING  | No codecarbon section defined in config
2025-01-26 20:39:24,596  | py-experimenter - INFO     | Initialized and connected to database
2025-01-26 20:39:24,650  | py-experimenter - INFO     | 4 rows successfully added to database. 0 rows were skipped.
2025-01-26 20:39:25,174  | py-experimenter - ERROR    | Traceback (most recent call last):
  File "/home/jonas/anaconda3/envs/plnet/lib/python3.11/site-packages/py_experimenter/experimenter.py", line 433, in _execute_experiment
    final_status = experiment_function(keyfield_values, result_processor, self.config.custom_configuration.custom_values)
                   ^^^^^^^^^^^^^^^^^^^^^^^^^^^^^^^^^^^^^^^^^^^^^^^^^^^^^^^^^^^^^^^^^^^^^^^^^^^^^^^^^^^^^^^^^^^^^^^^^^^^^^
  File "/home/jonas/Documents/Research/torch_plnet/experiments/simple_experiment_torchcp.py", line 366, in worker
    model = LabelRankingModel(
            ^^^^^^^^^^^^^^^^^^
  File "/home/jonas/Documents/Research/torch_plnet/models/ranking_models.py", line 56, in __init__
    for hidden_size in hidden_dims:
TypeError: 'int' object is not iterable

2025-01-26 20:39:25,258  | py-experimenter - ERROR    | Traceback (most recent call last):
  File "/home/jonas/anaconda3/envs/plnet/lib/python3.11/site-packages/py_experimenter/experimenter.py", line 433, in _execute_experiment
    final_status = experiment_function(keyfield_values, result_processor, self.config.custom_configuration.custom_values)
                   ^^^^^^^^^^^^^^^^^^^^^^^^^^^^^^^^^^^^^^^^^^^^^^^^^^^^^^^^^^^^^^^^^^^^^^^^^^^^^^^^^^^^^^^^^^^^^^^^^^^^^^
  File "/home/jonas/Documents/Research/torch_plnet/experiments/simple_experiment_torchcp.py", line 366, in worker
    model = LabelRankingModel(
            ^^^^^^^^^^^^^^^^^^
  File "/home/jonas/Documents/Research/torch_plnet/models/ranking_models.py", line 56, in __init__
    for hidden_size in hidden_dims:
TypeError: 'int' object is not iterable

2025-01-26 20:40:21,475  | py-experimenter - INFO     | All configured executions finished.
2025-01-26 20:42:55,923  | py-experimenter - INFO     | Found 4 keyfields
2025-01-26 20:42:55,923  | py-experimenter - INFO     | Found 2 resultfields
2025-01-26 20:42:55,923  | py-experimenter - INFO     | Found 1 logtables
2025-01-26 20:42:55,923  | py-experimenter - INFO     | Found logtable cp_rank_dev__new_cross__results
2025-01-26 20:42:55,923  | py-experimenter - WARNING  | No custom section defined in config
2025-01-26 20:42:55,924  | py-experimenter - WARNING  | No codecarbon section defined in config
2025-01-26 20:42:55,924  | py-experimenter - INFO     | Initialized and connected to database
2025-01-26 20:42:55,975  | py-experimenter - INFO     | 4 rows successfully added to database. 0 rows were skipped.
2025-01-26 20:42:59,703  | py-experimenter - ERROR    | Traceback (most recent call last):
  File "/home/jonas/anaconda3/envs/plnet/lib/python3.11/site-packages/py_experimenter/experimenter.py", line 433, in _execute_experiment
    final_status = experiment_function(keyfield_values, result_processor, self.config.custom_configuration.custom_values)
                   ^^^^^^^^^^^^^^^^^^^^^^^^^^^^^^^^^^^^^^^^^^^^^^^^^^^^^^^^^^^^^^^^^^^^^^^^^^^^^^^^^^^^^^^^^^^^^^^^^^^^^^
  File "/home/jonas/Documents/Research/torch_plnet/experiments/simple_experiment_torchcp.py", line 384, in worker
    if not isinstance(X_test, np.ndarray):
                      ^^^^^^
UnboundLocalError: cannot access local variable 'X_test' where it is not associated with a value

2025-01-26 20:43:00,180  | py-experimenter - ERROR    | Traceback (most recent call last):
  File "/home/jonas/anaconda3/envs/plnet/lib/python3.11/site-packages/py_experimenter/experimenter.py", line 433, in _execute_experiment
    final_status = experiment_function(keyfield_values, result_processor, self.config.custom_configuration.custom_values)
                   ^^^^^^^^^^^^^^^^^^^^^^^^^^^^^^^^^^^^^^^^^^^^^^^^^^^^^^^^^^^^^^^^^^^^^^^^^^^^^^^^^^^^^^^^^^^^^^^^^^^^^^
  File "/home/jonas/Documents/Research/torch_plnet/experiments/simple_experiment_torchcp.py", line 384, in worker
    if not isinstance(X_test, np.ndarray):
                      ^^^^^^
UnboundLocalError: cannot access local variable 'X_test' where it is not associated with a value

2025-01-26 20:43:14,380  | py-experimenter - ERROR    | Traceback (most recent call last):
  File "/home/jonas/anaconda3/envs/plnet/lib/python3.11/site-packages/py_experimenter/experimenter.py", line 433, in _execute_experiment
    final_status = experiment_function(keyfield_values, result_processor, self.config.custom_configuration.custom_values)
                   ^^^^^^^^^^^^^^^^^^^^^^^^^^^^^^^^^^^^^^^^^^^^^^^^^^^^^^^^^^^^^^^^^^^^^^^^^^^^^^^^^^^^^^^^^^^^^^^^^^^^^^
  File "/home/jonas/Documents/Research/torch_plnet/experiments/simple_experiment_torchcp.py", line 384, in worker
    if not isinstance(X_test, np.ndarray):
                      ^^^^^^
UnboundLocalError: cannot access local variable 'X_test' where it is not associated with a value

2025-01-26 20:45:22,635  | py-experimenter - INFO     | All configured executions finished.
2025-01-26 20:46:18,652  | py-experimenter - INFO     | Found 4 keyfields
2025-01-26 20:46:18,652  | py-experimenter - INFO     | Found 2 resultfields
2025-01-26 20:46:18,652  | py-experimenter - INFO     | Found 1 logtables
2025-01-26 20:46:18,652  | py-experimenter - INFO     | Found logtable cp_rank_dev__new_cross__results
2025-01-26 20:46:18,652  | py-experimenter - WARNING  | No custom section defined in config
2025-01-26 20:46:18,652  | py-experimenter - WARNING  | No codecarbon section defined in config
2025-01-26 20:46:18,652  | py-experimenter - INFO     | Initialized and connected to database
2025-01-26 20:46:18,696  | py-experimenter - INFO     | 4 rows successfully added to database. 0 rows were skipped.
2025-01-26 20:46:21,947  | py-experimenter - ERROR    | Traceback (most recent call last):
  File "/home/jonas/anaconda3/envs/plnet/lib/python3.11/site-packages/py_experimenter/experimenter.py", line 433, in _execute_experiment
    final_status = experiment_function(keyfield_values, result_processor, self.config.custom_configuration.custom_values)
                   ^^^^^^^^^^^^^^^^^^^^^^^^^^^^^^^^^^^^^^^^^^^^^^^^^^^^^^^^^^^^^^^^^^^^^^^^^^^^^^^^^^^^^^^^^^^^^^^^^^^^^^
  File "/home/jonas/Documents/Research/torch_plnet/experiments/simple_experiment_torchcp.py", line 396, in worker
    gradient_updates = predictor._model.gradient_updates
                       ^^^^^^^^^^^^^^^^
AttributeError: 'ConformalPredictor' object has no attribute '_model'

2025-01-26 20:46:23,706  | py-experimenter - ERROR    | Traceback (most recent call last):
  File "/home/jonas/anaconda3/envs/plnet/lib/python3.11/site-packages/py_experimenter/experimenter.py", line 433, in _execute_experiment
    final_status = experiment_function(keyfield_values, result_processor, self.config.custom_configuration.custom_values)
                   ^^^^^^^^^^^^^^^^^^^^^^^^^^^^^^^^^^^^^^^^^^^^^^^^^^^^^^^^^^^^^^^^^^^^^^^^^^^^^^^^^^^^^^^^^^^^^^^^^^^^^^
  File "/home/jonas/Documents/Research/torch_plnet/experiments/simple_experiment_torchcp.py", line 396, in worker
    gradient_updates = predictor._model.gradient_updates
                       ^^^^^^^^^^^^^^^^
AttributeError: 'ConformalPredictor' object has no attribute '_model'

2025-01-26 20:46:34,335  | py-experimenter - ERROR    | Traceback (most recent call last):
  File "/home/jonas/anaconda3/envs/plnet/lib/python3.11/site-packages/py_experimenter/experimenter.py", line 433, in _execute_experiment
    final_status = experiment_function(keyfield_values, result_processor, self.config.custom_configuration.custom_values)
                   ^^^^^^^^^^^^^^^^^^^^^^^^^^^^^^^^^^^^^^^^^^^^^^^^^^^^^^^^^^^^^^^^^^^^^^^^^^^^^^^^^^^^^^^^^^^^^^^^^^^^^^
  File "/home/jonas/Documents/Research/torch_plnet/experiments/simple_experiment_torchcp.py", line 396, in worker
    gradient_updates = predictor._model.gradient_updates
                       ^^^^^^^^^^^^^^^^
AttributeError: 'ConformalPredictor' object has no attribute '_model'

2025-01-26 20:46:38,357  | py-experimenter - INFO     | All configured executions finished.
2025-01-26 20:50:23,903  | py-experimenter - INFO     | Found 4 keyfields
2025-01-26 20:50:23,903  | py-experimenter - INFO     | Found 2 resultfields
2025-01-26 20:50:23,903  | py-experimenter - INFO     | Found 1 logtables
2025-01-26 20:50:23,903  | py-experimenter - INFO     | Found logtable cp_rank_dev__new_cross__results
2025-01-26 20:50:23,903  | py-experimenter - WARNING  | No custom section defined in config
2025-01-26 20:50:23,903  | py-experimenter - WARNING  | No codecarbon section defined in config
2025-01-26 20:50:23,903  | py-experimenter - INFO     | Initialized and connected to database
2025-01-26 20:50:23,950  | py-experimenter - INFO     | 4 rows successfully added to database. 0 rows were skipped.
2025-01-26 20:50:27,224  | py-experimenter - ERROR    | Traceback (most recent call last):
  File "/home/jonas/anaconda3/envs/plnet/lib/python3.11/site-packages/py_experimenter/experimenter.py", line 433, in _execute_experiment
    final_status = experiment_function(keyfield_values, result_processor, self.config.custom_configuration.custom_values)
                   ^^^^^^^^^^^^^^^^^^^^^^^^^^^^^^^^^^^^^^^^^^^^^^^^^^^^^^^^^^^^^^^^^^^^^^^^^^^^^^^^^^^^^^^^^^^^^^^^^^^^^^
  File "/home/jonas/Documents/Research/torch_plnet/experiments/simple_experiment_torchcp.py", line 379, in worker
    predictor = ConformalPredictor(estimator=model)
                ^^^^^^^^^^^^^^^^^^^^^^^^^^^^^^^^^^^
TypeError: ConformalPredictor.__init__() got an unexpected keyword argument 'estimator'

2025-01-26 20:50:27,319  | py-experimenter - ERROR    | Traceback (most recent call last):
  File "/home/jonas/anaconda3/envs/plnet/lib/python3.11/site-packages/py_experimenter/experimenter.py", line 433, in _execute_experiment
    final_status = experiment_function(keyfield_values, result_processor, self.config.custom_configuration.custom_values)
                   ^^^^^^^^^^^^^^^^^^^^^^^^^^^^^^^^^^^^^^^^^^^^^^^^^^^^^^^^^^^^^^^^^^^^^^^^^^^^^^^^^^^^^^^^^^^^^^^^^^^^^^
  File "/home/jonas/Documents/Research/torch_plnet/experiments/simple_experiment_torchcp.py", line 379, in worker
    predictor = ConformalPredictor(estimator=model)
                ^^^^^^^^^^^^^^^^^^^^^^^^^^^^^^^^^^^
TypeError: ConformalPredictor.__init__() got an unexpected keyword argument 'estimator'

2025-01-26 20:50:44,697  | py-experimenter - ERROR    | Traceback (most recent call last):
  File "/home/jonas/anaconda3/envs/plnet/lib/python3.11/site-packages/py_experimenter/experimenter.py", line 433, in _execute_experiment
    final_status = experiment_function(keyfield_values, result_processor, self.config.custom_configuration.custom_values)
                   ^^^^^^^^^^^^^^^^^^^^^^^^^^^^^^^^^^^^^^^^^^^^^^^^^^^^^^^^^^^^^^^^^^^^^^^^^^^^^^^^^^^^^^^^^^^^^^^^^^^^^^
  File "/home/jonas/Documents/Research/torch_plnet/experiments/simple_experiment_torchcp.py", line 379, in worker
    predictor = ConformalPredictor(estimator=model)
                ^^^^^^^^^^^^^^^^^^^^^^^^^^^^^^^^^^^
TypeError: ConformalPredictor.__init__() got an unexpected keyword argument 'estimator'

2025-01-26 20:50:44,976  | py-experimenter - ERROR    | Traceback (most recent call last):
  File "/home/jonas/anaconda3/envs/plnet/lib/python3.11/site-packages/py_experimenter/experimenter.py", line 433, in _execute_experiment
    final_status = experiment_function(keyfield_values, result_processor, self.config.custom_configuration.custom_values)
                   ^^^^^^^^^^^^^^^^^^^^^^^^^^^^^^^^^^^^^^^^^^^^^^^^^^^^^^^^^^^^^^^^^^^^^^^^^^^^^^^^^^^^^^^^^^^^^^^^^^^^^^
  File "/home/jonas/Documents/Research/torch_plnet/experiments/simple_experiment_torchcp.py", line 379, in worker
    predictor = ConformalPredictor(estimator=model)
                ^^^^^^^^^^^^^^^^^^^^^^^^^^^^^^^^^^^
TypeError: ConformalPredictor.__init__() got an unexpected keyword argument 'estimator'

2025-01-26 20:51:09,746  | py-experimenter - ERROR    | Traceback (most recent call last):
  File "/home/jonas/anaconda3/envs/plnet/lib/python3.11/site-packages/py_experimenter/database_connector.py", line 57, in execute
    cursor.execute(sql_statement, values)
sqlite3.OperationalError: no such table: cp_rank_dev__new_cross__results

During handling of the above exception, another exception occurred:

Traceback (most recent call last):
  File "/home/jonas/anaconda3/envs/plnet/lib/python3.11/site-packages/py_experimenter/experimenter.py", line 433, in _execute_experiment
    final_status = experiment_function(keyfield_values, result_processor, self.config.custom_configuration.custom_values)
                   ^^^^^^^^^^^^^^^^^^^^^^^^^^^^^^^^^^^^^^^^^^^^^^^^^^^^^^^^^^^^^^^^^^^^^^^^^^^^^^^^^^^^^^^^^^^^^^^^^^^^^^
  File "/home/jonas/Documents/Research/torch_plnet/experiments/simple_experiment_torchcp.py", line 305, in worker
    evaluate(
  File "/home/jonas/Documents/Research/torch_plnet/experiments/simple_experiment_torchcp.py", line 183, in evaluate
    result_processor.process_logs({"results": metrics})
  File "/home/jonas/anaconda3/envs/plnet/lib/python3.11/site-packages/py_experimenter/result_processor.py", line 89, in process_logs
    self.db_connector.execute_queries(queries)
  File "/home/jonas/anaconda3/envs/plnet/lib/python3.11/site-packages/py_experimenter/database_connector.py", line 377, in execute_queries
    self.execute(cursor, query[0], tuple(query[1]))
  File "/home/jonas/anaconda3/envs/plnet/lib/python3.11/site-packages/py_experimenter/database_connector.py", line 59, in execute
    raise DatabaseConnectionError(f"error \n{e}\n raised when executing sql statement.")
py_experimenter.exceptions.DatabaseConnectionError: error 
no such table: cp_rank_dev__new_cross__results
 raised when executing sql statement.

2025-01-26 20:51:20,393  | py-experimenter - INFO     | Found 4 keyfields
2025-01-26 20:51:20,393  | py-experimenter - INFO     | Found 2 resultfields
2025-01-26 20:51:20,393  | py-experimenter - INFO     | Found 1 logtables
2025-01-26 20:51:20,393  | py-experimenter - INFO     | Found logtable cp_rank_dev__new_cross__results
2025-01-26 20:51:20,393  | py-experimenter - WARNING  | No custom section defined in config
2025-01-26 20:51:20,393  | py-experimenter - WARNING  | No codecarbon section defined in config
2025-01-26 20:51:20,394  | py-experimenter - INFO     | Initialized and connected to database
2025-01-26 20:51:20,449  | py-experimenter - INFO     | 4 rows successfully added to database. 0 rows were skipped.
2025-01-26 20:51:25,646  | py-experimenter - ERROR    | Traceback (most recent call last):
  File "/home/jonas/anaconda3/envs/plnet/lib/python3.11/site-packages/py_experimenter/experimenter.py", line 433, in _execute_experiment
    final_status = experiment_function(keyfield_values, result_processor, self.config.custom_configuration.custom_values)
                   ^^^^^^^^^^^^^^^^^^^^^^^^^^^^^^^^^^^^^^^^^^^^^^^^^^^^^^^^^^^^^^^^^^^^^^^^^^^^^^^^^^^^^^^^^^^^^^^^^^^^^^
  File "/home/jonas/Documents/Research/torch_plnet/experiments/simple_experiment_torchcp.py", line 397, in worker
    evaluate(
  File "/home/jonas/Documents/Research/torch_plnet/experiments/simple_experiment_torchcp.py", line 120, in evaluate
    val_prediction_sets = torch.cat(predictions_sets_list, dim=0)  # (N_val x C)
                          ^^^^^^^^^^^^^^^^^^^^^^^^^^^^^^^^^^^^^^^
TypeError: expected Tensor as element 0 in argument 0, but got tuple

2025-01-26 20:51:48,312  | py-experimenter - ERROR    | Traceback (most recent call last):
  File "/home/jonas/anaconda3/envs/plnet/lib/python3.11/site-packages/py_experimenter/experimenter.py", line 433, in _execute_experiment
    final_status = experiment_function(keyfield_values, result_processor, self.config.custom_configuration.custom_values)
                   ^^^^^^^^^^^^^^^^^^^^^^^^^^^^^^^^^^^^^^^^^^^^^^^^^^^^^^^^^^^^^^^^^^^^^^^^^^^^^^^^^^^^^^^^^^^^^^^^^^^^^^
  File "/home/jonas/Documents/Research/torch_plnet/experiments/simple_experiment_torchcp.py", line 397, in worker
    evaluate(
  File "/home/jonas/Documents/Research/torch_plnet/experiments/simple_experiment_torchcp.py", line 120, in evaluate
    val_prediction_sets = torch.cat(predictions_sets_list, dim=0)  # (N_val x C)
                          ^^^^^^^^^^^^^^^^^^^^^^^^^^^^^^^^^^^^^^^
TypeError: expected Tensor as element 0 in argument 0, but got tuple

2025-01-26 20:53:47,832  | py-experimenter - INFO     | All configured executions finished.
2025-01-26 21:20:48,655  | py-experimenter - INFO     | Found 4 keyfields
2025-01-26 21:20:48,655  | py-experimenter - INFO     | Found 2 resultfields
2025-01-26 21:20:48,656  | py-experimenter - INFO     | Found 1 logtables
2025-01-26 21:20:48,656  | py-experimenter - INFO     | Found logtable cp_rank_dev__new_cross__results
2025-01-26 21:20:48,656  | py-experimenter - WARNING  | No custom section defined in config
2025-01-26 21:20:48,656  | py-experimenter - WARNING  | No codecarbon section defined in config
2025-01-26 21:20:48,657  | py-experimenter - INFO     | Initialized and connected to database
2025-01-26 21:20:48,715  | py-experimenter - INFO     | 2 rows successfully added to database. 0 rows were skipped.
2025-01-26 21:20:52,851  | py-experimenter - ERROR    | Traceback (most recent call last):
  File "/home/jonas/anaconda3/envs/plnet/lib/python3.11/site-packages/py_experimenter/experimenter.py", line 433, in _execute_experiment
    final_status = experiment_function(keyfield_values, result_processor, self.config.custom_configuration.custom_values)
                   ^^^^^^^^^^^^^^^^^^^^^^^^^^^^^^^^^^^^^^^^^^^^^^^^^^^^^^^^^^^^^^^^^^^^^^^^^^^^^^^^^^^^^^^^^^^^^^^^^^^^^^
  File "/home/jonas/Documents/Research/torch_plnet/experiments/simple_experiment_torchcp.py", line 397, in worker
    evaluate(
  File "/home/jonas/Documents/Research/torch_plnet/experiments/simple_experiment_torchcp.py", line 120, in evaluate
    val_prediction_sets = torch.cat(predictions_sets_list, dim=0)  # (N_val x C)
                          ^^^^^^^^^^^^^^^^^^^^^^^^^^^^^^^^^^^^^^^
TypeError: expected Tensor as element 0 in argument 0, but got tuple

2025-01-26 21:21:08,550  | py-experimenter - ERROR    | Traceback (most recent call last):
  File "/home/jonas/anaconda3/envs/plnet/lib/python3.11/site-packages/py_experimenter/experimenter.py", line 433, in _execute_experiment
    final_status = experiment_function(keyfield_values, result_processor, self.config.custom_configuration.custom_values)
                   ^^^^^^^^^^^^^^^^^^^^^^^^^^^^^^^^^^^^^^^^^^^^^^^^^^^^^^^^^^^^^^^^^^^^^^^^^^^^^^^^^^^^^^^^^^^^^^^^^^^^^^
  File "/home/jonas/Documents/Research/torch_plnet/experiments/simple_experiment_torchcp.py", line 397, in worker
    evaluate(
  File "/home/jonas/Documents/Research/torch_plnet/experiments/simple_experiment_torchcp.py", line 120, in evaluate
    val_prediction_sets = torch.cat(predictions_sets_list, dim=0)  # (N_val x C)
                          ^^^^^^^^^^^^^^^^^^^^^^^^^^^^^^^^^^^^^^^
TypeError: expected Tensor as element 0 in argument 0, but got tuple

2025-01-26 21:21:08,846  | py-experimenter - ERROR    | Traceback (most recent call last):
  File "/home/jonas/anaconda3/envs/plnet/lib/python3.11/site-packages/py_experimenter/experimenter.py", line 433, in _execute_experiment
    final_status = experiment_function(keyfield_values, result_processor, self.config.custom_configuration.custom_values)
                   ^^^^^^^^^^^^^^^^^^^^^^^^^^^^^^^^^^^^^^^^^^^^^^^^^^^^^^^^^^^^^^^^^^^^^^^^^^^^^^^^^^^^^^^^^^^^^^^^^^^^^^
  File "/home/jonas/Documents/Research/torch_plnet/experiments/simple_experiment_torchcp.py", line 397, in worker
    evaluate(
  File "/home/jonas/Documents/Research/torch_plnet/experiments/simple_experiment_torchcp.py", line 120, in evaluate
    val_prediction_sets = torch.cat(predictions_sets_list, dim=0)  # (N_val x C)
                          ^^^^^^^^^^^^^^^^^^^^^^^^^^^^^^^^^^^^^^^
TypeError: expected Tensor as element 0 in argument 0, but got tuple

2025-01-26 21:21:08,900  | py-experimenter - INFO     | All configured executions finished.
2025-01-26 21:29:54,195  | py-experimenter - INFO     | Found 4 keyfields
2025-01-26 21:29:54,195  | py-experimenter - INFO     | Found 2 resultfields
2025-01-26 21:29:54,196  | py-experimenter - INFO     | Found 1 logtables
2025-01-26 21:29:54,196  | py-experimenter - INFO     | Found logtable cp_rank_dev__new_cross__results
2025-01-26 21:29:54,197  | py-experimenter - WARNING  | No custom section defined in config
2025-01-26 21:29:54,197  | py-experimenter - WARNING  | No codecarbon section defined in config
2025-01-26 21:29:54,198  | py-experimenter - INFO     | Initialized and connected to database
2025-01-26 21:29:54,252  | py-experimenter - INFO     | 2 rows successfully added to database. 0 rows were skipped.
2025-01-26 21:30:15,194  | py-experimenter - INFO     | All configured executions finished.
2025-01-26 21:45:03,756  | py-experimenter - INFO     | Found 4 keyfields
2025-01-26 21:45:03,756  | py-experimenter - INFO     | Found 2 resultfields
2025-01-26 21:45:03,757  | py-experimenter - INFO     | Found 1 logtables
2025-01-26 21:45:03,757  | py-experimenter - INFO     | Found logtable cp_rank_dev__new_cross__results
2025-01-26 21:45:03,757  | py-experimenter - WARNING  | No custom section defined in config
2025-01-26 21:45:03,757  | py-experimenter - WARNING  | No codecarbon section defined in config
2025-01-26 21:45:03,758  | py-experimenter - INFO     | Initialized and connected to database
2025-01-26 21:45:03,815  | py-experimenter - INFO     | 1 rows successfully added to database. 0 rows were skipped.
2025-01-26 21:45:36,110  | py-experimenter - INFO     | All configured executions finished.
